Workbook

Sheet Config
A1: Configurations | C1: Dry mass [kg] | D1: Nominal Thrust [N] | E1: ISP [s] | F1: core O/F [-] | G1: Mass flow tot core [kg/s] | H1: Mass flow ox [kg/s] | I1: Mass flow fuel core [kg/s] | J1: Ramp up time [s] | K1: Ramp down time [s] | L1: Total impulse burn [Ns] | M1: Total impulse [Ns] | N1: Description
A2: Firehorn 1 | C2: 84.4 | D2: 6308 | E2: 198 | F2: 1.463 | G2: 3.248 | H2: 1.925 | I2: 1.306 | J2: 0.361 | K2: 0.171 | L2: 36000 | M2: 36167 | N2: B1 flight configuration of FH1 for reference
A3: THRUST1 | B3: 2026_C_PR_B3_CONFIG1 | C3: 95.66 | D3: 5000 | E3: 240 | F3: 1.5 | G3: =D3/(E3*9.81) -> 2.1236833 | H3: =G3/(1+1/F3) -> 1.27421 | I3: =G3 / (1 +F3 ) -> 0.84947333 | J3: 0.4 | K3: 0.2 | N3: B3, dry mass = est, thrust iteration for exit velocity
B4: 2025_C_PR_B3_CONFIG2 | C4: 95.66 | D4: 5500 | E4: 240 | F4: 1.5 | G4: =D4/(E4*9.81) -> 2.3360516 | H4: =G4/(1+1/F4) -> 1.401631 | I4: =G4 / (1 +F4 ) -> 0.93442066 | J4: 0.4 | K4: 0.2 | N4: B3, dry mass = est, thrust iteration for exit velocity
B5: 2026_C_PR_B3_CONFIG3 | C5: 95.66 | D5: 6000 | E5: 240 | F5: 1.5 | G5: =D5/(E5*9.81) -> 2.54842 | H5: =G5/(1+1/F5) -> 1.529052 | I5: =G5 / (1 +F5 ) -> 1.019368 | J5: 0.4 | K5: 0.2 | N5: B3, dry mass = est, thrust iteration for exit velocity
B6: 2025_C_PR_B3_CONFIG4 | C6: 95.66 | D6: 6500 | E6: 240 | F6: 1.5 | G6: =D6/(E6*9.81) -> 2.7607883 | H6: =G6/(1+1/F6) -> 1.656473 | I6: =G6 / (1 +F6 ) -> 1.1043153 | J6: 0.4 | K6: 0.2 | L6: 36000 | M6: =L6 + J6*D6/2 + K6*D6/2 -> 37950 | N6: B3, dry mass = est, thrust iteration for exit velocity
B7: 2026_C_PR_B3_CONFIG5 | C7: 95.66 | D7: 7000 | E7: 240 | F7: 1.5 | G7: =D7/(E7*9.81) -> 2.9731566 | H7: =G7/(1+1/F7) -> 1.783894 | I7: =G7 / (1 +F7 ) -> 1.1892627 | J7: 0.4 | K7: 0.2 | L7: 36000 | M7: =L7 + J7*D7/2 + K7*D7/2 -> 38100 | N7: B3, dry mass = est, thrust iteration for exit velocity
B8: 2025_C_PR_B3_CONFIG6 | C8: 95.66 | D8: 7500 | E8: 240 | F8: 1.5 | G8: =D8/(E8*9.81) -> 3.185525 | H8: =G8/(1+1/F8) -> 1.911315 | I8: =G8 / (1 +F8 ) -> 1.27421 | J8: 0.4 | K8: 0.2 | N8: B3, dry mass = est, thrust iteration for exit velocity
B9: 2026_C_PR_B3_CONFIG7 | C9: 95.66 | D9: 1 | E9: 240 | F9: 1.5 | G9: =D9/(E9*9.81) -> 0.00042473666 | H9: =G9/(1+1/F9) -> 0.000254842 | I9: =G9 / (1 +F9 ) -> 0.00016989467 | J9: 0.4 | K9: 0.2 | N9: B3, dry mass = est, thrust iteration for exit velocity
B10: 2025_C_PR_B3_CONFIG8 | C10: 95.66 | D10: 1 | E10: 240 | F10: 1.5 | G10: =D10/(E10*9.81) -> 0.00042473666 | H10: =G10/(1+1/F10) -> 0.000254842 | I10: =G10 / (1 +F10 ) -> 0.00016989467 | J10: 0.4 | K10: 0.2 | N10: B3, dry mass = est, thrust iteration for exit velocity
B11: 2026_C_PR_B3_CONFIG9 | C11: 95.66 | D11: 1 | E11: 240 | F11: 1.5 | G11: =D11/(E11*9.81) -> 0.00042473666 | H11: =G11/(1+1/F11) -> 0.000254842 | I11: =G11 / (1 +F11 ) -> 0.00016989467 | J11: 0.4 | K11: 0.2 | N11: B3, dry mass = est, thrust iteration for exit velocity
B12: 2026_C_PR_B3_CONFIG10 | C12: 95.66 | D12: 1 | E12: 240 | F12: 1.5 | G12: =D12/(E12*9.81) -> 0.00042473666 | H12: =G12/(1+1/F12) -> 0.000254842 | I12: =G12 / (1 +F12 ) -> 0.00016989467 | J12: 0.4 | K12: 0.2 | N12: B3, dry mass = est, thrust iteration for exit velocity
B13: 2026_C_PR_B3_CONFIG11 | C13: 95.66 | D13: 1 | E13: 240 | F13: 1.5 | G13: =D13/(E13*9.81) -> 0.00042473666 | H13: =G13/(1+1/F13) -> 0.000254842 | I13: =G13 / (1 +F13 ) -> 0.00016989467 | J13: 0.4 | K13: 0.2 | N13: B3, dry mass = est, thrust iteration for exit velocity
B14: 2026_C_PR_B3_CONFIG12 | C14: 95.66 | D14: 1 | E14: 240 | F14: 1.5 | G14: =D14/(E14*9.81) -> 0.00042473666 | H14: =G14/(1+1/F14) -> 0.000254842 | I14: =G14 / (1 +F14 ) -> 0.00016989467 | J14: 0.4 | K14: 0.2 | N14: B3, dry mass = est, thrust iteration for exit velocity
A15: THRUST2 | B15: 2026_C_PR_B3_CONFIG13 | C15: 107.28 | D15: 5000 | E15: 240 | F15: 1.5 | G15: =D15/(E15*9.81) -> 2.1236833 | H15: =G15/(1+1/F15) -> 1.27421 | I15: =G15 / (1 +F15 ) -> 0.84947333 | J15: 0.4 | K15: 0.2 | N15: B3, dry mass = est + 15%, thrust iteration for exit velocity
B16: 2026_C_PR_B3_CONFIG14 | C16: 107.28 | D16: 5500 | E16: 240 | F16: 1.5 | G16: =D16/(E16*9.81) -> 2.3360516 | H16: =G16/(1+1/F16) -> 1.401631 | I16: =G16 / (1 +F16 ) -> 0.93442066 | J16: 0.4 | K16: 0.2 | N16: B3, dry mass = est + 15%, thrust iteration for exit velocity
B17: 2026_C_PR_B3_CONFIG15 | C17: 107.28 | D17: 6000 | E17: 240 | F17: 1.5 | G17: =D17/(E17*9.81) -> 2.54842 | H17: =G17/(1+1/F17) -> 1.529052 | I17: =G17 / (1 +F17 ) -> 1.019368 | J17: 0.4 | K17: 0.2 | N17: B3, dry mass = est + 15%, thrust iteration for exit velocity
B18: 2026_C_PR_B3_CONFIG16 | C18: 107.28 | D18: 6500 | E18: 240 | F18: 1.5 | G18: =D18/(E18*9.81) -> 2.7607883 | H18: =G18/(1+1/F18) -> 1.656473 | I18: =G18 / (1 +F18 ) -> 1.1043153 | J18: 0.4 | K18: 0.2 | N18: B3, dry mass = est + 15%, thrust iteration for exit velocity
B19: 2026_C_PR_B3_CONFIG17 | C19: 107.28 | D19: 7000 | E19: 240 | F19: 1.5 | G19: =D19/(E19*9.81) -> 2.9731566 | H19: =G19/(1+1/F19) -> 1.783894 | I19: =G19 / (1 +F19 ) -> 1.1892627 | J19: 0.4 | K19: 0.2 | N19: B3, dry mass = est + 15%, thrust iteration for exit velocity
B20: 2026_C_PR_B3_CONFIG18 | C20: 107.28 | D20: 7500 | E20: 240 | F20: 1.5 | G20: =D20/(E20*9.81) -> 3.185525 | H20: =G20/(1+1/F20) -> 1.911315 | I20: =G20 / (1 +F20 ) -> 1.27421 | J20: 0.4 | K20: 0.2 | L20: 36000 | M20: =L20 + J20*D20/2 + K20*D20/2 -> 38250 | N20: B3, dry mass = est + 15%, thrust iteration for exit velocity
B21: 2026_C_PR_B3_CONFIG19 | C21: 107.28 | D21: 8000 | E21: 240 | F21: 1.5 | G21: =D21/(E21*9.81) -> 3.3978933 | H21: =G21/(1+1/F21) -> 2.038736 | I21: =G21 / (1 +F21 ) -> 1.3591573 | J21: 0.4 | K21: 0.2 | L21: 36000 | M21: =L21 + J21*D21/2 + K21*D21/2 -> 38400 | N21: B3, dry mass = est + 15%, thrust iteration for exit velocity
B22: 2026_C_PR_B3_CONFIG20 | C22: 107.28 | D22: 1 | E22: 240 | F22: 1.5 | G22: =D22/(E22*9.81) -> 0.00042473666 | H22: =G22/(1+1/F22) -> 0.000254842 | I22: =G22 / (1 +F22 ) -> 0.00016989467 | J22: 0.4 | K22: 0.2 | N22: B3, dry mass = est + 15%, thrust iteration for exit velocity
B23: 2026_C_PR_B3_CONFIG21 | C23: 107.28 | D23: 1 | E23: 240 | F23: 1.5 | G23: =D23/(E23*9.81) -> 0.00042473666 | H23: =G23/(1+1/F23) -> 0.000254842 | I23: =G23 / (1 +F23 ) -> 0.00016989467 | J23: 0.4 | K23: 0.2 | N23: B3, dry mass = est + 15%, thrust iteration for exit velocity
B24: 2026_C_PR_B3_CONFIG22 | C24: 107.28 | D24: 1 | E24: 240 | F24: 1.5 | G24: =D24/(E24*9.81) -> 0.00042473666 | H24: =G24/(1+1/F24) -> 0.000254842 | I24: =G24 / (1 +F24 ) -> 0.00016989467 | J24: 0.4 | K24: 0.2 | N24: B3, dry mass = est + 15%, thrust iteration for exit velocity
B25: 2026_C_PR_B3_CONFIG23 | C25: 107.28 | D25: 1 | E25: 240 | F25: 1.5 | G25: =D25/(E25*9.81) -> 0.00042473666 | H25: =G25/(1+1/F25) -> 0.000254842 | I25: =G25 / (1 +F25 ) -> 0.00016989467 | J25: 0.4 | K25: 0.2 | N25: B3, dry mass = est + 15%, thrust iteration for exit velocity
B26: 2026_C_PR_B3_CONFIG24 | C26: 107.28 | D26: 1 | E26: 240 | F26: 1.5 | G26: =D26/(E26*9.81) -> 0.00042473666 | H26: =G26/(1+1/F26) -> 0.000254842 | I26: =G26 / (1 +F26 ) -> 0.00016989467 | J26: 0.4 | K26: 0.2 | N26: B3, dry mass = est + 15%, thrust iteration for exit velocity
A27: IMPULSE1 | B27: 2026_C_PR_B3_CONFIG25 | C27: 95.66 | D27: 7000 | E27: 240 | F27: 1.5 | G27: =D27/(E27*9.81) -> 2.9731566 | H27: =G27/(1+1/F27) -> 1.783894 | I27: =G27 / (1 +F27 ) -> 1.1892627 | J27: 0.4 | K27: 0.2 | L27: 35000 | M27: =L27 + J27*D27/2 + K27*D27/2 -> 37100 | N27: B3, dry mass = est, impulse iteration for apogee
B28: 2026_C_PR_B3_CONFIG26 | C28: 95.66 | D28: 7000 | E28: 240 | F28: 1.5 | G28: =D28/(E28*9.81) -> 2.9731566 | H28: =G28/(1+1/F28) -> 1.783894 | I28: =G28 / (1 +F28 ) -> 1.1892627 | J28: 0.4 | K28: 0.2 | L28: 37500 | M28: =L28 + J28*D28/2 + K28*D28/2 -> 39600 | N28: B3, dry mass = est, impulse iteration for apogee
B29: 2026_C_PR_B3_CONFIG27 | C29: 95.66 | D29: 7000 | E29: 240 | F29: 1.5 | G29: =D29/(E29*9.81) -> 2.9731566 | H29: =G29/(1+1/F29) -> 1.783894 | I29: =G29 / (1 +F29 ) -> 1.1892627 | J29: 0.4 | K29: 0.2 | L29: 36000 | M29: =L29 + J29*D29/2 + K29*D29/2 -> 38100 | N29: B3, dry mass = est, impulse iteration for apogee
B30: 2026_C_PR_B3_CONFIG28 | C30: 95.66 | D30: 7000 | E30: 240 | F30: 1.5 | G30: =D30/(E30*9.81) -> 2.9731566 | H30: =G30/(1+1/F30) -> 1.783894 | I30: =G30 / (1 +F30 ) -> 1.1892627 | J30: 0.4 | K30: 0.2 | L30: 36500 | M30: =L30 + J30*D30/2 + K30*D30/2 -> 38600 | N30: B3, dry mass = est, impulse iteration for apogee
B31: 2026_C_PR_B3_CONFIG29 | C31: 95.66 | D31: 7000 | E31: 240 | F31: 1.5 | G31: =D31/(E31*9.81) -> 2.9731566 | H31: =G31/(1+1/F31) -> 1.783894 | I31: =G31 / (1 +F31 ) -> 1.1892627 | J31: 0.4 | K31: 0.2 | L31: 36750 | M31: =L31 + J31*D31/2 + K31*D31/2 -> 38850 | N31: B3, dry mass = est, impulse iteration for apogee
B32: 2026_C_PR_B3_CONFIG30 | C32: 95.66 | D32: 1 | E32: 240 | F32: 1.5 | G32: =D32/(E32*9.81) -> 0.00042473666 | H32: =G32/(1+1/F32) -> 0.000254842 | I32: =G32 / (1 +F32 ) -> 0.00016989467 | J32: 0.4 | K32: 0.2 | L32: 1 | M32: =L32 + J32*D32/2 + K32*D32/2 -> 1.3 | N32: B3, dry mass = est, impulse iteration for apogee
A33: IMPULSE2 | B33: 2026_C_PR_B3_CONFIG31 | C33: 107.28 | D33: 8000 | E33: 240 | F33: 1.5 | G33: =D33/(E33*9.81) -> 3.3978933 | H33: =G33/(1+1/F33) -> 2.038736 | I33: =G33 / (1 +F33 ) -> 1.3591573 | J33: 0.4 | K33: 0.2 | L33: 37000 | M33: =L33 + J33*D33/2 + K33*D33/2 -> 39400 | N33: B3, dry mass = est + 15%, impulse iteration for apogee
B34: 2026_C_PR_B3_CONFIG32 | C34: 107.28 | D34: 8000 | E34: 240 | F34: 1.5 | G34: =D34/(E34*9.81) -> 3.3978933 | H34: =G34/(1+1/F34) -> 2.038736 | I34: =G34 / (1 +F34 ) -> 1.3591573 | J34: 0.4 | K34: 0.2 | L34: 37500 | M34: =L34 + J34*D34/2 + K34*D34/2 -> 39900 | N34: B3, dry mass = est + 15%, impulse iteration for apogee
B35: 2026_C_PR_B3_CONFIG33 | C35: 107.28 | D35: 8000 | E35: 240 | F35: 1.5 | G35: =D35/(E35*9.81) -> 3.3978933 | H35: =G35/(1+1/F35) -> 2.038736 | I35: =G35 / (1 +F35 ) -> 1.3591573 | J35: 0.4 | K35: 0.2 | L35: 1 | M35: =L35 + J35*D35/2 + K35*D35/2 -> 2401 | N35: B3, dry mass = est + 15%, impulse iteration for apogee
B36: 2026_C_PR_B3_CONFIG34 | C36: 107.28 | D36: 8000 | E36: 240 | F36: 1.5 | G36: =D36/(E36*9.81) -> 3.3978933 | H36: =G36/(1+1/F36) -> 2.038736 | I36: =G36 / (1 +F36 ) -> 1.3591573 | J36: 0.4 | K36: 0.2 | L36: 1 | M36: =L36 + J36*D36/2 + K36*D36/2 -> 2401 | N36: B3, dry mass = est + 15%, impulse iteration for apogee
B37: 2026_C_PR_B1_CONFIG35 | C37: 107.28 | D37: 1 | E37: 240 | F37: 1.5 | G37: =D37/(E37*9.81) -> 0.00042473666 | H37: =G37/(1+1/F37) -> 0.000254842 | I37: =G37 / (1 +F37 ) -> 0.00016989467 | J37: 0.4 | K37: 0.2 | L37: 1 | M37: =L37 + J37*D37/2 + K37*D37/2 -> 1.3 | N37: B3, dry mass = est + 15%, impulse iteration for apogee
B38: 2026_C_PR_B1_CONFIG36 | C38: 107.28 | D38: 1 | E38: 240 | F38: 1.5 | G38: =D38/(E38*9.81) -> 0.00042473666 | H38: =G38/(1+1/F38) -> 0.000254842 | I38: =G38 / (1 +F38 ) -> 0.00016989467 | J38: 0.4 | K38: 0.2 | L38: 1 | M38: =L38 + J38*D38/2 + K38*D38/2 -> 1.3 | N38: B3, dry mass = est + 15%, impulse iteration for apogee
A39: ISP | B39: 2026_C_PR_B1_CONFIG37 | C39: 95.66 | D39: 7000 | E39: 200 | F39: 1.5 | G39: =D39/(E39*9.81) -> 3.567788 | H39: =G39/(1+1/F39) -> 2.1406728 | I39: =G39 / (1 +F39 ) -> 1.4271152 | J39: 0.4 | K39: 0.2 | L39: 36750 | M39: =L39 + J39*D39/2 + K39*D39/2 -> 38850 | N39: B3, dry mass = est, ISP iteration
B40: 2026_C_PR_B1_CONFIG38 | C40: 95.66 | D40: 7000 | E40: 205 | F40: 1.5 | G40: =D40/(E40*9.81) -> 3.4807688 | H40: =G40/(1+1/F40) -> 2.0884613 | I40: =G40 / (1 +F40 ) -> 1.3923075 | J40: 0.4 | K40: 0.2 | L40: 36750 | M40: =L40 + J40*D40/2 + K40*D40/2 -> 38850 | N40: B3, dry mass = est, ISP iteration
...

Sheet Budget
B1: Timings | C1: Hold | D1: Prechill | E1: Ignition | F1: Ramp Up | G1: Burn | H1: Cutoff | I1: Ramp Down
B2: variables | C2: hold_time | D2: prechill_time | E2: ignition_delay | F2: ramp_up_duration | G2: nominal_duration | H2: cutoff_time | I2: ramp_down_duration
A3: Firehorn 1 | C3: 300 | D3: 0.2 | E3: -0.05 | F3: 0.153 | G3: 6.69 | H3: 0.025 | I3: 0.247
C4: =549+90 -> 639 | D4: 0.2 | E4: -0.05 | F4: 0.361 | G4: 1.082 | H4: 0.025 | I4: 0.171
A5: THRUST1 | B5: =Config!B3 -> 2026_C_PR_B3_CONFIG1 | C5: 300 | D5: 0.2 | E5: -0.05 | F5: =Config!J3 -> 0.4 | G5: =Config!L3/Config!D3 -> 0 | H5: 0.025 | I5: =Config!K3 -> 0.2
B6: =Config!B4 -> 2025_C_PR_B3_CONFIG2 | C6: 300 | D6: 0.2 | E6: -0.05 | F6: =Config!J4 -> 0.4 | G6: =Config!L4/Config!D4 -> 0 | H6: 0.025 | I6: =Config!K4 -> 0.2
B7: =Config!B5 -> 2026_C_PR_B3_CONFIG3 | C7: 300 | D7: 0.2 | E7: -0.05 | F7: =Config!J5 -> 0.4 | G7: =Config!L5/Config!D5 -> 0 | H7: 0.025 | I7: =Config!K5 -> 0.2
B8: =Config!B6 -> 2025_C_PR_B3_CONFIG4 | C8: 300 | D8: 0.2 | E8: -0.05 | F8: =Config!J6 -> 0.4 | G8: =Config!L6/Config!D6 -> 5.5384615 | H8: 0.025 | I8: =Config!K6 -> 0.2
B9: =Config!B7 -> 2026_C_PR_B3_CONFIG5 | C9: 300 | D9: 0.2 | E9: -0.05 | F9: =Config!J7 -> 0.4 | G9: =Config!L7/Config!D7 -> 5.1428571 | H9: 0.025 | I9: =Config!K7 -> 0.2
B10: =Config!B8 -> 2025_C_PR_B3_CONFIG6 | C10: 300 | D10: 0.2 | E10: -0.05 | F10: =Config!J8 -> 0.4 | G10: =Config!L8/Config!D8 -> 0 | H10: 0.025 | I10: =Config!K8 -> 0.2
B11: =Config!B9 -> 2026_C_PR_B3_CONFIG7 | C11: 300 | D11: 0.2 | E11: -0.05 | F11: =Config!J9 -> 0.4 | G11: =Config!L9/Config!D9 -> 0 | H11: 0.025 | I11: =Config!K9 -> 0.2
B12: =Config!B10 -> 2025_C_PR_B3_CONFIG8 | C12: 300 | D12: 0.2 | E12: -0.05 | F12: =Config!J10 -> 0.4 | G12: =Config!L10/Config!D10 -> 0 | H12: 0.025 | I12: =Config!K10 -> 0.2
B13: =Config!B11 -> 2026_C_PR_B3_CONFIG9 | C13: 300 | D13: 0.2 | E13: -0.05 | F13: =Config!J11 -> 0.4 | G13: =Config!L11/Config!D11 -> 0 | H13: 0.025 | I13: =Config!K11 -> 0.2
B14: =Config!B12 -> 2026_C_PR_B3_CONFIG10 | C14: 300 | D14: 0.2 | E14: -0.05 | F14: =Config!J12 -> 0.4 | G14: =Config!L12/Config!D12 -> 0 | H14: 0.025 | I14: =Config!K12 -> 0.2
B15: =Config!B13 -> 2026_C_PR_B3_CONFIG11 | C15: 300 | D15: 0.2 | E15: -0.05 | F15: =Config!J13 -> 0.4 | G15: =Config!L13/Config!D13 -> 0 | H15: 0.025 | I15: =Config!K13 -> 0.2
B16: =Config!B14 -> 2026_C_PR_B3_CONFIG12 | C16: 300 | D16: 0.2 | E16: -0.05 | F16: =Config!J14 -> 0.4 | G16: =Config!L14/Config!D14 -> 0 | H16: 0.025 | I16: =Config!K14 -> 0.2
A17: THRUST2 | B17: =Config!B15 -> 2026_C_PR_B3_CONFIG13 | C17: 300 | D17: 0.2 | E17: -0.05 | F17: =Config!J15 -> 0.4 | G17: =Config!L15/Config!D15 -> 0 | H17: 0.025 | I17: =Config!K15 -> 0.2
B18: =Config!B16 -> 2026_C_PR_B3_CONFIG14 | C18: 300 | D18: 0.2 | E18: -0.05 | F18: =Config!J16 -> 0.4 | G18: =Config!L16/Config!D16 -> 0 | H18: 0.025 | I18: =Config!K16 -> 0.2
B19: =Config!B17 -> 2026_C_PR_B3_CONFIG15 | C19: 300 | D19: 0.2 | E19: -0.05 | F19: =Config!J17 -> 0.4 | G19: =Config!L17/Config!D17 -> 0 | H19: 0.025 | I19: =Config!K17 -> 0.2
B20: =Config!B18 -> 2026_C_PR_B3_CONFIG16 | C20: 300 | D20: 0.2 | E20: -0.05 | F20: =Config!J18 -> 0.4 | G20: =Config!L18/Config!D18 -> 0 | H20: 0.025 | I20: =Config!K18 -> 0.2
B21: =Config!B19 -> 2026_C_PR_B3_CONFIG17 | C21: 300 | D21: 0.2 | E21: -0.05 | F21: =Config!J19 -> 0.4 | G21: =Config!L19/Config!D19 -> 0 | H21: 0.025 | I21: =Config!K19 -> 0.2
B22: =Config!B20 -> 2026_C_PR_B3_CONFIG18 | C22: 300 | D22: 0.2 | E22: -0.05 | F22: =Config!J20 -> 0.4 | G22: =Config!L20/Config!D20 -> 4.8 | H22: 0.025 | I22: =Config!K20 -> 0.2
B23: =Config!B21 -> 2026_C_PR_B3_CONFIG19 | C23: 300 | D23: 0.2 | E23: -0.05 | F23: =Config!J21 -> 0.4 | G23: =Config!L21/Config!D21 -> 4.5 | H23: 0.025 | I23: =Config!K21 -> 0.2
B24: =Config!B22 -> 2026_C_PR_B3_CONFIG20 | C24: 300 | D24: 0.2 | E24: -0.05 | F24: =Config!J22 -> 0.4 | G24: =Config!M22/Config!D22 -> 0 | H24: 0.025 | I24: =Config!K22 -> 0.2
B25: =Config!B23 -> 2026_C_PR_B3_CONFIG21 | C25: 300 | D25: 0.2 | E25: -0.05 | F25: =Config!J23 -> 0.4 | G25: =Config!M23/Config!D23 -> 0 | H25: 0.025 | I25: =Config!K23 -> 0.2
B26: =Config!B24 -> 2026_C_PR_B3_CONFIG22 | C26: 300 | D26: 0.2 | E26: -0.05 | F26: =Config!J24 -> 0.4 | G26: =Config!M24/Config!D24 -> 0 | H26: 0.025 | I26: =Config!K24 -> 0.2
B27: =Config!B25 -> 2026_C_PR_B3_CONFIG23 | C27: 300 | D27: 0.2 | E27: -0.05 | F27: =Config!J25 -> 0.4 | G27: =Config!M25/Config!D25 -> 0 | H27: 0.025 | I27: =Config!K25 -> 0.2
B28: =Config!B26 -> 2026_C_PR_B3_CONFIG24 | C28: 300 | D28: 0.2 | E28: -0.05 | F28: =Config!J26 -> 0.4 | G28: =Config!M26/Config!D26 -> 0 | H28: 0.025 | I28: =Config!K26 -> 0.2
A29: IMPULSE1 | B29: =Config!B27 -> 2026_C_PR_B3_CONFIG25 | C29: 300 | D29: 0.2 | E29: -0.05 | F29: =Config!J27 -> 0.4 | G29: =Config!L27/Config!D27 -> 5 | H29: 0.025 | I29: =Config!K27 -> 0.2
B30: =Config!B28 -> 2026_C_PR_B3_CONFIG26 | C30: 300 | D30: 0.2 | E30: -0.05 | F30: =Config!J28 -> 0.4 | G30: =Config!L28/Config!D28 -> 5.3571429 | H30: 0.025 | I30: =Config!K28 -> 0.2
B31: =Config!B29 -> 2026_C_PR_B3_CONFIG27 | C31: 300 | D31: 0.2 | E31: -0.05 | F31: =Config!J29 -> 0.4 | G31: =Config!L29/Config!D29 -> 5.1428571 | H31: 0.025 | I31: =Config!K29 -> 0.2
B32: =Config!B30 -> 2026_C_PR_B3_CONFIG28 | C32: 300 | D32: 0.2 | E32: -0.05 | F32: =Config!J30 -> 0.4 | G32: =Config!L30/Config!D30 -> 5.2142857 | H32: 0.025 | I32: =Config!K30 -> 0.2
B33: =Config!B31 -> 2026_C_PR_B3_CONFIG29 | C33: 300 | D33: 0.2 | E33: -0.05 | F33: =Config!J31 -> 0.4 | G33: =Config!L31/Config!D31 -> 5.25 | H33: 0.025 | I33: =Config!K31 -> 0.2
B34: =Config!B32 -> 2026_C_PR_B3_CONFIG30 | C34: 300 | D34: 0.2 | E34: -0.05 | F34: =Config!J32 -> 0.4 | G34: =Config!L32/Config!D32 -> 1 | H34: 0.025 | I34: =Config!K32 -> 0.2
A35: IMPULSE2 | B35: =Config!B33 -> 2026_C_PR_B3_CONFIG31 | C35: 300 | D35: 0.2 | E35: -0.05 | F35: =Config!J33 -> 0.4 | G35: =Config!M33/Config!D33 -> 4.925 | H35: 0.025 | I35: =Config!K33 -> 0.2
B36: =Config!B34 -> 2026_C_PR_B3_CONFIG32 | C36: 300 | D36: 0.2 | E36: -0.05 | F36: =Config!J34 -> 0.4 | G36: =Config!M34/Config!D34 -> 4.9875 | H36: 0.025 | I36: =Config!K34 -> 0.2
B37: =Config!B35 -> 2026_C_PR_B3_CONFIG33 | C37: 300 | D37: 0.2 | E37: -0.05 | F37: =Config!J35 -> 0.4 | G37: =Config!M35/Config!D35 -> 0.300125 | H37: 0.025 | I37: =Config!K35 -> 0.2
B38: =Config!B36 -> 2026_C_PR_B3_CONFIG34 | C38: 300 | D38: 0.2 | E38: -0.05 | F38: =Config!J36 -> 0.4 | G38: =Config!M36/Config!D36 -> 0.300125 | H38: 0.025 | I38: =Config!K36 -> 0.2
B39: =Config!B37 -> 2026_C_PR_B1_CONFIG35 | C39: 639 | D39: 0.2 | E39: -0.05 | F39: =Config!J37 -> 0.4 | G39: =Config!M37/Config!D37 -> 1.3 | H39: 0.025 | I39: =Config!K37 -> 0.2
B40: =Config!B38 -> 2026_C_PR_B1_CONFIG36 | C40: 639 | D40: 0.2 | E40: -0.05 | F40: =Config!J38 -> 0.4 | G40: =Config!M38/Config!D38 -> 1.3 | H40: 0.025 | I40: =Config!K38 -> 0.2
...

Sheet Simulations
B2: Simulations inputs | D2: N2 | E2: Oxidizer | G2: Fuel | I2: Thrust [N] | K2: Total Impulse | L2: Timing [s] | O2: Description | Q2: Simulations outputs | S2: Apogee [m] | T2: Rail exit static margin [c] | U2: Rail exit velocity [m/s] | V2: Description
D3: Mass total [kg] | E3: Mass total [kg] | F3: Mass remaining [kg] | G3: Mass total [kg] | H3: Mass remaining [kg] | I3: Full | J3: Derated | L3: Ramp up | M3: Burn time | N3: Ramp down
B4: Firehorn 1 | D4: =Budget!E56 -> 2.605 | E4: =Budget!R109 -> 13.647 | F4: =Budget!Q109 -> 2.67 | G4: =Budget!R162 -> 9.639 | H4: =Budget!Q162 -> 0.527 | I4: =Config!D2 -> 6308 | J4: ND | K4: =Config!M2 -> 36167 | L4: =Budget!F4 -> 0.361 | M4: =Budget!G3 -> 6.69 | N4: =Budget!I4 -> 0.171 | O4: B1 flight configuration of FH1 for reference (no simulation needed) | Q4: Firehorn 1 | S4: / | T4: / | U4: / | V4: B1 flight configuration of FH1 for reference (no simulation needed)
B5: THRUST1 | C5: =Config!B3 -> 2026_C_PR_B3_CONFIG1 | D5: =Budget!E58 -> 5.21037 | E5: =Budget!R111 - Budget!L111 - Budget!M111 - Budget!Q111 -> 0.2181 | F5: =Budget!Q111 -> 0.577 | G5: =Budget!R164 -Budget!Q164 -> 0.022829596 | H5: =Budget!Q164 -> 0.405 | I5: =Config!D3 -> 5000 | J5: =Config!D3 -> 5000 | K5: =Config!M3 -> 0 | L5: =Budget!F5 -> 0.4 | M5: =Budget!G5 -> 0 | N5: =Budget!I5 -> 0.2 | O5: =Config!N3 -> B3, dry mass = est, thrust iteration for exit velocity | Q5: THRUST1 | R5: =Config!B3 -> 2026_C_PR_B3_CONFIG1 | V5: =Config!N3 -> B3, dry mass = est, thrust iteration for exit velocity
C6: =Config!B4 -> 2025_C_PR_B3_CONFIG2 | D6: =Budget!E59 -> 5.21037 | E6: =Budget!R112 - Budget!L112 - Budget!M112 - Budget!Q112 -> 0.2181 | F6: =Budget!Q112 -> 0.577 | G6: =Budget!R165 -Budget!Q165 -> 0.025112555 | H6: =Budget!Q165 -> 0.405 | I6: =Config!D4 -> 5500 | J6: =Config!D4 -> 5500 | K6: =Config!M4 -> 0 | L6: =Budget!F6 -> 0.4 | M6: =Budget!G6 -> 0 | N6: =Budget!I6 -> 0.2 | O6: =Config!N4 -> B3, dry mass = est, thrust iteration for exit velocity | R6: =Config!B4 -> 2025_C_PR_B3_CONFIG2 | V6: =Config!N4 -> B3, dry mass = est, thrust iteration for exit velocity
C7: =Config!B5 -> 2026_C_PR_B3_CONFIG3 | D7: =Budget!E60 -> 5.21037 | E7: =Budget!R113 - Budget!L113 - Budget!M113 - Budget!Q113 -> 0.2181 | F7: =Budget!Q113 -> 0.577 | G7: =Budget!R166 -Budget!Q166 -> 0.027395515 | H7: =Budget!Q166 -> 0.405 | I7: =Config!D5 -> 6000 | J7: =Config!D5 -> 6000 | K7: =Config!M5 -> 0 | L7: =Budget!F7 -> 0.4 | M7: =Budget!G7 -> 0 | N7: =Budget!I7 -> 0.2 | O7: =Config!N5 -> B3, dry mass = est, thrust iteration for exit velocity | R7: =Config!B5 -> 2026_C_PR_B3_CONFIG3 | V7: =Config!N5 -> B3, dry mass = est, thrust iteration for exit velocity
C8: =Config!B6 -> 2025_C_PR_B3_CONFIG4 | D8: =Budget!E61 -> 5.21037 | E8: =Budget!R114 - Budget!L114 - Budget!M114 - Budget!Q114 -> 9.3924119 | F8: =Budget!Q114 -> 0.577 | G8: =Budget!R167 -Budget!Q167 -> 6.604602 | H8: =Budget!Q167 -> 0.405 | I8: =Config!D6 -> 6500 | J8: =Config!D6 -> 6500 | K8: 36000 | L8: =Budget!F8 -> 0.4 | M8: =Budget!G8 -> 5.5384615 | N8: =Budget!I8 -> 0.2 | O8: =Config!N6 -> B3, dry mass = est, thrust iteration for exit velocity | R8: =Config!B6 -> 2025_C_PR_B3_CONFIG4 | S8: 3172 | T8: 3.601 | U8: 30.557 | V8: =Config!N6 -> B3, dry mass = est, thrust iteration for exit velocity
C9: =Config!B7 -> 2026_C_PR_B3_CONFIG5 | D9: =Budget!E62 -> 5.21037 | E9: =Budget!R115 - Budget!L115 - Budget!M115 - Budget!Q115 -> 9.3924119 | F9: =Budget!Q115 -> 0.577 | G9: =Budget!R168 -Budget!Q168 -> 6.606885 | H9: =Budget!Q168 -> 0.405 | I9: =Config!D7 -> 7000 | J9: =Config!D7 -> 7000 | K9: 36000 | L9: =Budget!F9 -> 0.4 | M9: =Budget!G9 -> 5.1428571 | N9: =Budget!I9 -> 0.2 | O9: =Config!N7 -> B3, dry mass = est, thrust iteration for exit velocity | R9: =Config!B7 -> 2026_C_PR_B3_CONFIG5 | S9: 3267 | T9: 3.6 | U9: 31.951 | V9: =Config!N7 -> B3, dry mass = est, thrust iteration for exit velocity
C10: =Config!B8 -> 2025_C_PR_B3_CONFIG6 | D10: =Budget!E63 -> 5.21037 | E10: =Budget!R116 - Budget!L116 - Budget!M116 - Budget!Q116 -> 0.2181 | F10: =Budget!Q116 -> 0.577 | G10: =Budget!R169 -Budget!Q169 -> 0.034244393 | H10: =Budget!Q169 -> 0.405 | I10: =Config!D8 -> 7500 | J10: =Config!D8 -> 7500 | K10: =Config!M8 -> 0 | L10: =Budget!F10 -> 0.4 | M10: =Budget!G10 -> 0 | N10: =Budget!I10 -> 0.2 | O10: =Config!N8 -> B3, dry mass = est, thrust iteration for exit velocity | R10: =Config!B8 -> 2025_C_PR_B3_CONFIG6 | V10: =Config!N8 -> B3, dry mass = est, thrust iteration for exit velocity
C11: =Config!B9 -> 2026_C_PR_B3_CONFIG7 | D11: =Budget!E64 -> 5.21037 | E11: =Budget!R117 - Budget!L117 - Budget!M117 - Budget!Q117 -> 0.2181 | F11: =Budget!Q117 -> 0.577 | G11: =Budget!R170 -Budget!Q170 -> 4.5659191e-06 | H11: =Budget!Q170 -> 0.405 | I11: =Config!D9 -> 1 | J11: =Config!D9 -> 1 | K11: =Config!M9 -> 0 | L11: =Budget!F11 -> 0.4 | M11: =Budget!G11 -> 0 | N11: =Budget!I11 -> 0.2 | O11: =Config!N9 -> B3, dry mass = est, thrust iteration for exit velocity | R11: =Config!B9 -> 2026_C_PR_B3_CONFIG7 | V11: =Config!N9 -> B3, dry mass = est, thrust iteration for exit velocity
C12: =Config!B10 -> 2025_C_PR_B3_CONFIG8 | D12: =Budget!E65 -> 5.21037 | E12: =Budget!R118 - Budget!L118 - Budget!M118 - Budget!Q118 -> 0.2181 | F12: =Budget!Q118 -> 0.577 | G12: =Budget!R171 -Budget!Q171 -> 4.5659191e-06 | H12: =Budget!Q171 -> 0.405 | I12: =Config!D10 -> 1 | J12: =Config!D10 -> 1 | K12: =Config!M10 -> 0 | L12: =Budget!F12 -> 0.4 | M12: =Budget!G12 -> 0 | N12: =Budget!I12 -> 0.2 | O12: =Config!N10 -> B3, dry mass = est, thrust iteration for exit velocity | R12: =Config!B10 -> 2025_C_PR_B3_CONFIG8 | V12: =Config!N10 -> B3, dry mass = est, thrust iteration for exit velocity
C13: =Config!B11 -> 2026_C_PR_B3_CONFIG9 | D13: =Budget!E66 -> 5.21037 | E13: =Budget!R119 - Budget!L119 - Budget!M119 - Budget!Q119 -> 0.2181 | F13: =Budget!Q119 -> 0.577 | G13: =Budget!R172 -Budget!Q172 -> 4.5659191e-06 | H13: =Budget!Q172 -> 0.405 | I13: =Config!D11 -> 1 | J13: =Config!D11 -> 1 | K13: =Config!M11 -> 0 | L13: =Budget!F13 -> 0.4 | M13: =Budget!G13 -> 0 | N13: =Budget!I13 -> 0.2 | O13: =Config!N11 -> B3, dry mass = est, thrust iteration for exit velocity | R13: =Config!B11 -> 2026_C_PR_B3_CONFIG9 | V13: =Config!N11 -> B3, dry mass = est, thrust iteration for exit velocity
C14: =Config!B12 -> 2026_C_PR_B3_CONFIG10 | D14: =Budget!E67 -> 5.21037 | E14: =Budget!R120 - Budget!L120 - Budget!M120 - Budget!Q120 -> 0.2181 | F14: =Budget!Q120 -> 0.577 | G14: =Budget!R173 -Budget!Q173 -> 4.5659191e-06 | H14: =Budget!Q173 -> 0.405 | I14: =Config!D12 -> 1 | J14: =Config!D12 -> 1 | K14: =Config!M12 -> 0 | L14: =Budget!F14 -> 0.4 | M14: =Budget!G14 -> 0 | N14: =Budget!I14 -> 0.2 | O14: =Config!N12 -> B3, dry mass = est, thrust iteration for exit velocity | R14: =Config!B12 -> 2026_C_PR_B3_CONFIG10 | V14: =Config!N12 -> B3, dry mass = est, thrust iteration for exit velocity
C15: =Config!B13 -> 2026_C_PR_B3_CONFIG11 | D15: =Budget!E68 -> 5.21037 | E15: =Budget!R121 - Budget!L121 - Budget!M121 - Budget!Q121 -> 0.2181 | F15: =Budget!Q121 -> 0.577 | G15: =Budget!R174 -Budget!Q174 -> 4.5659191e-06 | H15: =Budget!Q174 -> 0.405 | I15: =Config!D13 -> 1 | J15: =Config!D13 -> 1 | K15: =Config!M13 -> 0 | L15: =Budget!F15 -> 0.4 | M15: =Budget!G15 -> 0 | N15: =Budget!I15 -> 0.2 | O15: =Config!N13 -> B3, dry mass = est, thrust iteration for exit velocity | R15: =Config!B13 -> 2026_C_PR_B3_CONFIG11 | V15: =Config!N13 -> B3, dry mass = est, thrust iteration for exit velocity
C16: =Config!B14 -> 2026_C_PR_B3_CONFIG12 | D16: =Budget!E69 -> 5.21037 | E16: =Budget!R122 - Budget!L122 - Budget!M122 - Budget!Q122 -> 0.2181 | F16: =Budget!Q122 -> 0.577 | G16: =Budget!R175 -Budget!Q175 -> 4.5659191e-06 | H16: =Budget!Q175 -> 0.405 | I16: =Config!D14 -> 1 | J16: =Config!D14 -> 1 | K16: =Config!M14 -> 0 | L16: =Budget!F16 -> 0.4 | M16: =Budget!G16 -> 0 | N16: =Budget!I16 -> 0.2 | O16: =Config!N14 -> B3, dry mass = est, thrust iteration for exit velocity | R16: =Config!B14 -> 2026_C_PR_B3_CONFIG12 | V16: =Config!N14 -> B3, dry mass = est, thrust iteration for exit velocity
B17: THRUST2 | C17: =Config!B15 -> 2026_C_PR_B3_CONFIG13 | D17: =Budget!E70 -> 5.21037 | E17: =Budget!R123 - Budget!L123 - Budget!M123 - Budget!Q123 -> 0.2181 | F17: =Budget!Q123 -> 0.577 | G17: =Budget!R176 -Budget!Q176 -> 0.022829596 | H17: =Budget!Q176 -> 0.405 | I17: =Config!D15 -> 5000 | J17: =Config!D15 -> 5000 | K17: =Config!M15 -> 0 | L17: =Budget!F17 -> 0.4 | M17: =Budget!G17 -> 0 | N17: =Budget!I17 -> 0.2 | O17: =Config!N15 -> B3, dry mass = est + 15%, thrust iteration for exit velocity | Q17: THRUST2 | R17: =Config!B15 -> 2026_C_PR_B3_CONFIG13 | V17: =Config!N15 -> B3, dry mass = est + 15%, thrust iteration for exit velocity
C18: =Config!B16 -> 2026_C_PR_B3_CONFIG14 | D18: =Budget!E71 -> 5.21037 | E18: =Budget!R124 - Budget!L124 - Budget!M124 - Budget!Q124 -> 0.2181 | F18: =Budget!Q124 -> 0.577 | G18: =Budget!R177 -Budget!Q177 -> 0.025112555 | H18: =Budget!Q177 -> 0.405 | I18: =Config!D16 -> 5500 | J18: =Config!D16 -> 5500 | K18: =Config!M16 -> 0 | L18: =Budget!F18 -> 0.4 | M18: =Budget!G18 -> 0 | N18: =Budget!I18 -> 0.2 | O18: =Config!N16 -> B3, dry mass = est + 15%, thrust iteration for exit velocity | R18: =Config!B16 -> 2026_C_PR_B3_CONFIG14 | V18: =Config!N16 -> B3, dry mass = est + 15%, thrust iteration for exit velocity
C19: =Config!B17 -> 2026_C_PR_B3_CONFIG15 | D19: =Budget!E72 -> 5.21037 | E19: =Budget!R125 - Budget!L125 - Budget!M125 - Budget!Q125 -> 0.2181 | F19: =Budget!Q125 -> 0.577 | G19: =Budget!R178 -Budget!Q178 -> 0.027395515 | H19: =Budget!Q178 -> 0.405 | I19: =Config!D17 -> 6000 | J19: =Config!D17 -> 6000 | K19: =Config!M17 -> 0 | L19: =Budget!F19 -> 0.4 | M19: =Budget!G19 -> 0 | N19: =Budget!I19 -> 0.2 | O19: =Config!N17 -> B3, dry mass = est + 15%, thrust iteration for exit velocity | R19: =Config!B17 -> 2026_C_PR_B3_CONFIG15 | V19: =Config!N17 -> B3, dry mass = est + 15%, thrust iteration for exit velocity
C20: =Config!B18 -> 2026_C_PR_B3_CONFIG16 | D20: =Budget!E73 -> 5.21037 | E20: =Budget!R126 - Budget!L126 - Budget!M126 - Budget!Q126 -> 0.2181 | F20: =Budget!Q126 -> 0.577 | G20: =Budget!R179 -Budget!Q179 -> 0.029678474 | H20: =Budget!Q179 -> 0.405 | I20: =Config!D18 -> 6500 | J20: =Config!D18 -> 6500 | K20: =Config!M18 -> 0 | L20: =Budget!F20 -> 0.4 | M20: =Budget!G20 -> 0 | N20: =Budget!I20 -> 0.2 | O20: =Config!N18 -> B3, dry mass = est + 15%, thrust iteration for exit velocity | R20: =Config!B18 -> 2026_C_PR_B3_CONFIG16 | V20: =Config!N18 -> B3, dry mass = est + 15%, thrust iteration for exit velocity
C21: =Config!B19 -> 2026_C_PR_B3_CONFIG17 | D21: =Budget!E74 -> 5.21037 | E21: =Budget!R127 - Budget!L127 - Budget!M127 - Budget!Q127 -> 0.2181 | F21: =Budget!Q127 -> 0.577 | G21: =Budget!R180 -Budget!Q180 -> 0.031961434 | H21: =Budget!Q180 -> 0.405 | I21: =Config!D19 -> 7000 | J21: =Config!D19 -> 7000 | K21: =Config!M19 -> 0 | L21: =Budget!F21 -> 0.4 | M21: =Budget!G21 -> 0 | N21: =Budget!I21 -> 0.2 | O21: =Config!N19 -> B3, dry mass = est + 15%, thrust iteration for exit velocity | R21: =Config!B19 -> 2026_C_PR_B3_CONFIG17 | V21: =Config!N19 -> B3, dry mass = est + 15%, thrust iteration for exit velocity
C22: =Config!B20 -> 2026_C_PR_B3_CONFIG18 | D22: =Budget!E75 -> 5.21037 | E22: =Budget!R128 - Budget!L128 - Budget!M128 - Budget!Q128 -> 9.3924119 | F22: =Budget!Q128 -> 0.577 | G22: =Budget!R181 -Budget!Q181 -> 6.6091679 | H22: =Budget!Q181 -> 0.405 | I22: =Config!D20 -> 7500 | J22: =Config!D20 -> 7500 | K22: 36000 | L22: =Budget!F22 -> 0.4 | M22: =Budget!G22 -> 4.8 | N22: =Budget!I22 -> 0.2 | O22: =Config!N20 -> B3, dry mass = est + 15%, thrust iteration for exit velocity | R22: =Config!B20 -> 2026_C_PR_B3_CONFIG18 | S22: 2740 | T22: 3.688 | U22: 31.696 | V22: =Config!N20 -> B3, dry mass = est + 15%, thrust iteration for exit velocity
C23: =Config!B21 -> 2026_C_PR_B3_CONFIG19 | D23: =Budget!E76 -> 5.21037 | E23: =Budget!R129 - Budget!L129 - Budget!M129 - Budget!Q129 -> 9.3924119 | F23: =Budget!Q129 -> 0.577 | G23: =Budget!R182 -Budget!Q182 -> 6.6114509 | H23: =Budget!Q182 -> 0.405 | I23: =Config!D21 -> 8000 | J23: =Config!D21 -> 8000 | K23: =Config!M21 -> 38400 | L23: =Budget!F23 -> 0.4 | M23: =Budget!G23 -> 4.5 | N23: =Budget!I23 -> 0.2 | O23: =Config!N21 -> B3, dry mass = est + 15%, thrust iteration for exit velocity | R23: =Config!B21 -> 2026_C_PR_B3_CONFIG19 | S23: 2777 | T23: 3.666 | U23: 32.817 | V23: =Config!N21 -> B3, dry mass = est + 15%, thrust iteration for exit velocity
C24: =Config!B22 -> 2026_C_PR_B3_CONFIG20 | D24: =Budget!E77 -> 5.21037 | E24: =Budget!R130 - Budget!L130 - Budget!M130 - Budget!Q130 -> 0.2181 | F24: =Budget!Q130 -> 0.577 | G24: =Budget!R183 -Budget!Q183 -> 4.5659191e-06 | H24: =Budget!Q183 -> 0.405 | I24: =Config!D22 -> 1 | J24: =Config!D22 -> 1 | K24: =Config!M22 -> 0 | L24: =Budget!F24 -> 0.4 | M24: =Budget!G24 -> 0 | N24: =Budget!I24 -> 0.2 | O24: =Config!N22 -> B3, dry mass = est + 15%, thrust iteration for exit velocity | R24: =Config!B22 -> 2026_C_PR_B3_CONFIG20 | V24: =Config!N22 -> B3, dry mass = est + 15%, thrust iteration for exit velocity
C25: =Config!B23 -> 2026_C_PR_B3_CONFIG21 | D25: =Budget!E78 -> 5.21037 | E25: =Budget!R131 - Budget!L131 - Budget!M131 - Budget!Q131 -> 0.2181 | F25: =Budget!Q131 -> 0.577 | G25: =Budget!R184 -Budget!Q184 -> 4.5659191e-06 | H25: =Budget!Q184 -> 0.405 | I25: =Config!D23 -> 1 | J25: =Config!D23 -> 1 | K25: =Config!M23 -> 0 | L25: =Budget!F25 -> 0.4 | M25: =Budget!G25 -> 0 | N25: =Budget!I25 -> 0.2 | O25: =Config!N23 -> B3, dry mass = est + 15%, thrust iteration for exit velocity | R25: =Config!B23 -> 2026_C_PR_B3_CONFIG21 | V25: =Config!N23 -> B3, dry mass = est + 15%, thrust iteration for exit velocity
C26: =Config!B24 -> 2026_C_PR_B3_CONFIG22 | D26: =Budget!E79 -> 5.21037 | E26: =Budget!R132 - Budget!L132 - Budget!M132 - Budget!Q132 -> 0.2181 | F26: =Budget!Q132 -> 0.577 | G26: =Budget!R185 -Budget!Q185 -> 4.5659191e-06 | H26: =Budget!Q185 -> 0.405 | I26: =Config!D24 -> 1 | J26: =Config!D24 -> 1 | K26: =Config!M24 -> 0 | L26: =Budget!F26 -> 0.4 | M26: =Budget!G26 -> 0 | N26: =Budget!I26 -> 0.2 | O26: =Config!N24 -> B3, dry mass = est + 15%, thrust iteration for exit velocity | R26: =Config!B24 -> 2026_C_PR_B3_CONFIG22 | V26: =Config!N24 -> B3, dry mass = est + 15%, thrust iteration for exit velocity
C27: =Config!B25 -> 2026_C_PR_B3_CONFIG23 | D27: =Budget!E80 -> 5.21037 | E27: =Budget!R133 - Budget!L133 - Budget!M133 - Budget!Q133 -> 0.2181 | F27: =Budget!Q133 -> 0.577 | G27: =Budget!R186 -Budget!Q186 -> 4.5659191e-06 | H27: =Budget!Q186 -> 0.405 | I27: =Config!D25 -> 1 | J27: =Config!D25 -> 1 | K27: =Config!M25 -> 0 | L27: =Budget!F27 -> 0.4 | M27: =Budget!G27 -> 0 | N27: =Budget!I27 -> 0.2 | O27: =Config!N25 -> B3, dry mass = est + 15%, thrust iteration for exit velocity | R27: =Config!B25 -> 2026_C_PR_B3_CONFIG23 | V27: =Config!N25 -> B3, dry mass = est + 15%, thrust iteration for exit velocity
C28: =Config!B26 -> 2026_C_PR_B3_CONFIG24 | D28: =Budget!E81 -> 5.21037 | E28: =Budget!R134 - Budget!L134 - Budget!M134 - Budget!Q134 -> 0.2181 | F28: =Budget!Q134 -> 0.577 | G28: =Budget!R187 -Budget!Q187 -> 4.5659191e-06 | H28: =Budget!Q187 -> 0.405 | I28: =Config!D26 -> 1 | J28: =Config!D26 -> 1 | K28: =Config!M26 -> 0 | L28: =Budget!F28 -> 0.4 | M28: =Budget!G28 -> 0 | N28: =Budget!I28 -> 0.2 | O28: =Config!N26 -> B3, dry mass = est + 15%, thrust iteration for exit velocity | R28: =Config!B26 -> 2026_C_PR_B3_CONFIG24 | V28: =Config!N26 -> B3, dry mass = est + 15%, thrust iteration for exit velocity
B29: IMPULSE1 | C29: =Config!B27 -> 2026_C_PR_B3_CONFIG25 | D29: =Budget!E82 -> 5.21037 | E29: =Budget!R135 - Budget!L135 - Budget!M135 - Budget!Q135 -> 9.1375699 | F29: =Budget!Q135 -> 0.577 | G29: =Budget!R188 -Budget!Q188 -> 6.4242482 | H29: =Budget!Q188 -> 0.405 | I29: =Config!D27 -> 7000 | J29: =Config!D27 -> 7000 | K29: =Config!M27 -> 37100 | L29: =Budget!F29 -> 0.4 | M29: =Budget!G29 -> 5 | N29: =Budget!I29 -> 0.2 | O29: =Config!N27 -> B3, dry mass = est, impulse iteration for apogee | Q29: IMPULSE1 | R29: =Config!B27 -> 2026_C_PR_B3_CONFIG25 | S29: 3008 | T29: 3.622 | U29: 32.087 | V29: =Config!N27 -> B3, dry mass = est, impulse iteration for apogee
C30: =Config!B28 -> 2026_C_PR_B3_CONFIG26 | D30: =Budget!E83 -> 5.21037 | E30: =Budget!R136 - Budget!L136 - Budget!M136 - Budget!Q136 -> 9.7746749 | F30: =Budget!Q136 -> 0.577 | G30: =Budget!R189 -Budget!Q189 -> 6.8808401 | H30: =Budget!Q189 -> 0.405 | I30: =Config!D28 -> 7000 | J30: =Config!D28 -> 7000 | K30: =Config!M28 -> 39600 | L30: =Budget!F30 -> 0.4 | M30: =Budget!G30 -> 5.3571429 | N30: =Budget!I30 -> 0.2 | O30: =Config!N28 -> B3, dry mass = est, impulse iteration for apogee | R30: =Config!B28 -> 2026_C_PR_B3_CONFIG26 | S30: 3315 | T30: 3.596 | U30: 31.929 | V30: =Config!N28 -> B3, dry mass = est, impulse iteration for apogee
C31: =Config!B29 -> 2026_C_PR_B3_CONFIG27 | D31: =Budget!E84 -> 5.21037 | E31: =Budget!R137 - Budget!L137 - Budget!M137 - Budget!Q137 -> 9.3924119 | F31: =Budget!Q137 -> 0.577 | G31: =Budget!R190 -Budget!Q190 -> 6.606885 | H31: =Budget!Q190 -> 0.405 | I31: =Config!D29 -> 7000 | J31: =Config!D29 -> 7000 | K31: =Config!M29 -> 38100 | L31: =Budget!F31 -> 0.4 | M31: =Budget!G31 -> 5.1428571 | N31: =Budget!I31 -> 0.2 | O31: =Config!N29 -> B3, dry mass = est, impulse iteration for apogee | R31: =Config!B29 -> 2026_C_PR_B3_CONFIG27 | S31: 3129 | T31: 3.612 | U31: 32.016 | V31: =Config!N29 -> B3, dry mass = est, impulse iteration for apogee
C32: =Config!B30 -> 2026_C_PR_B3_CONFIG28 | D32: =Budget!E85 -> 5.21037 | E32: =Budget!R138 - Budget!L138 - Budget!M138 - Budget!Q138 -> 9.5198329 | F32: =Budget!Q138 -> 0.577 | G32: =Budget!R191 -Budget!Q191 -> 6.6982034 | H32: =Budget!Q191 -> 0.405 | I32: =Config!D30 -> 7000 | J32: =Config!D30 -> 7000 | K32: =Config!M30 -> 38600 | L32: =Budget!F32 -> 0.4 | M32: =Budget!G32 -> 5.2142857 | N32: =Budget!I32 -> 0.2 | O32: =Config!N30 -> B3, dry mass = est, impulse iteration for apogee | R32: =Config!B30 -> 2026_C_PR_B3_CONFIG28 | S32: 3190 | T32: 3.606 | U32: 31.991 | V32: =Config!N30 -> B3, dry mass = est, impulse iteration for apogee
C33: =Config!B31 -> 2026_C_PR_B3_CONFIG29 | D33: =Budget!E86 -> 5.21037 | E33: =Budget!R139 - Budget!L139 - Budget!M139 - Budget!Q139 -> 9.5835434 | F33: =Budget!Q139 -> 0.577 | G33: =Budget!R192 -Budget!Q192 -> 6.7438626 | H33: =Budget!Q192 -> 0.405 | I33: =Config!D31 -> 7000 | J33: =Config!D31 -> 7000 | K33: =Config!M31 -> 38850 | L33: =Budget!F33 -> 0.4 | M33: =Budget!G33 -> 5.25 | N33: =Budget!I33 -> 0.2 | O33: =Config!N31 -> B3, dry mass = est, impulse iteration for apogee | R33: =Config!B31 -> 2026_C_PR_B3_CONFIG29 | S33: 3220 | T33: 3.604 | U33: 31.975 | V33: =Config!N31 -> B3, dry mass = est, impulse iteration for apogee
C34: =Config!B32 -> 2026_C_PR_B3_CONFIG30 | D34: =Budget!E87 -> 5.21037 | E34: =Budget!R140 - Budget!L140 - Budget!M140 - Budget!Q140 -> 0.21835484 | F34: =Budget!Q140 -> 0.577 | G34: =Budget!R193 -Budget!Q193 -> 0.00018720268 | H34: =Budget!Q193 -> 0.405 | I34: =Config!D32 -> 1 | J34: =Config!D32 -> 1 | K34: =Config!M32 -> 1.3 | L34: =Budget!F34 -> 0.4 | M34: =Budget!G34 -> 1 | N34: =Budget!I34 -> 0.2 | O34: =Config!N32 -> B3, dry mass = est, impulse iteration for apogee | R34: =Config!B32 -> 2026_C_PR_B3_CONFIG30 | V34: =Config!N32 -> B3, dry mass = est, impulse iteration for apogee
B35: IMPULSE2 | C35: =Config!B33 -> 2026_C_PR_B3_CONFIG31 | D35: =Budget!E88 -> 5.21037 | E35: =Budget!R141 - Budget!L141 - Budget!M141 - Budget!Q141 -> 10.258875 | F35: =Budget!Q141 -> 0.577 | G35: =Budget!R194 -Budget!Q194 -> 7.2324159 | H35: =Budget!Q194 -> 0.405 | I35: =Config!D33 -> 8000 | J35: 8000 | K35: =Config!M33 -> 39400 | L35: =Budget!F35 -> 0.4 | M35: =Budget!G35 -> 4.925 | N35: =Budget!I35 -> 0.2 | O35: =Config!N33 -> B3, dry mass = est + 15%, impulse iteration for apogee | Q35: IMPULSE2 | R35: =Config!B33 -> 2026_C_PR_B3_CONFIG31 | S35: 3192 | T35: 3.655 | U35: 32.743 | V35: =Config!N33 -> B3, dry mass = est + 15%, impulse iteration for apogee
C36: =Config!B34 -> 2026_C_PR_B3_CONFIG32 | D36: =Budget!E89 -> 5.21037 | E36: =Budget!R142 - Budget!L142 - Budget!M142 - Budget!Q142 -> 10.386296 | F36: =Budget!Q142 -> 0.577 | G36: =Budget!R195 -Budget!Q195 -> 7.3237343 | H36: =Budget!Q195 -> 0.405 | I36: =Config!D34 -> 8000 | J36: 8000 | K36: =Config!M34 -> 39900 | L36: =Budget!F36 -> 0.4 | M36: =Budget!G36 -> 4.9875 | N36: =Budget!I36 -> 0.2 | O36: =Config!N34 -> B3, dry mass = est + 15%, impulse iteration for apogee | R36: =Config!B34 -> 2026_C_PR_B3_CONFIG32 | S36: 3253 | T36: 3.651 | U36: 32.713 | V36: =Config!N34 -> B3, dry mass = est + 15%, impulse iteration for apogee
C37: =Config!B35 -> 2026_C_PR_B3_CONFIG33 | D37: =Budget!E90 -> 5.21037 | E37: =Budget!R143 - Budget!L143 - Budget!M143 - Budget!Q143 -> 0.82997564 | F37: =Budget!Q143 -> 0.577 | G37: =Budget!R196 -Budget!Q196 -> 0.47503823 | H37: =Budget!Q196 -> 0.405 | I37: =Config!D35 -> 8000 | J37: 8000 | K37: =Config!M35 -> 2401 | L37: =Budget!F37 -> 0.4 | M37: =Budget!G37 -> 0.300125 | N37: =Budget!I37 -> 0.2 | O37: =Config!N35 -> B3, dry mass = est + 15%, impulse iteration for apogee | R37: =Config!B35 -> 2026_C_PR_B3_CONFIG33 | V37: =Config!N35 -> B3, dry mass = est + 15%, impulse iteration for apogee
C38: =Config!B36 -> 2026_C_PR_B3_CONFIG34 | D38: =Budget!E91 -> 5.21037 | E38: =Budget!R144 - Budget!L144 - Budget!M144 - Budget!Q144 -> 0.82997564 | F38: =Budget!Q144 -> 0.577 | G38: =Budget!R197 -Budget!Q197 -> 0.47503823 | H38: =Budget!Q197 -> 0.405 | I38: =Config!D36 -> 8000 | J38: 8000 | K38: =Config!M36 -> 2401 | L38: =Budget!F38 -> 0.4 | M38: =Budget!G38 -> 0.300125 | N38: =Budget!I38 -> 0.2 | O38: =Config!N36 -> B3, dry mass = est + 15%, impulse iteration for apogee | R38: =Config!B36 -> 2026_C_PR_B3_CONFIG34 | V38: =Config!N36 -> B3, dry mass = est + 15%, impulse iteration for apogee
C39: =Config!B37 -> 2026_C_PR_B1_CONFIG35 | D39: =Budget!E92 -> 5.21037 | E39: =Budget!R145 - Budget!L145 - Budget!M145 - Budget!Q145 -> 0.21843129 | F39: =Budget!Q145 -> 0.577 | G39: =Budget!R198 -Budget!Q198 -> 0.16585011 | H39: =Budget!Q198 -> 0.405 | I39: =Config!D37 -> 1 | J39: =Config!D37 -> 1 | K39: =Config!M37 -> 1.3 | L39: =Budget!F39 -> 0.4 | M39: =Budget!G39 -> 1.3 | N39: =Budget!I39 -> 0.2 | O39: =Config!N37 -> B3, dry mass = est + 15%, impulse iteration for apogee | R39: =Config!B37 -> 2026_C_PR_B1_CONFIG35 | V39: =Config!N37 -> B3, dry mass = est + 15%, impulse iteration for apogee
C40: =Config!B38 -> 2026_C_PR_B1_CONFIG36 | D40: =Budget!E93 -> 5.21037 | E40: =Budget!R146 - Budget!L146 - Budget!M146 - Budget!Q146 -> 0.21843129 | F40: =Budget!Q146 -> 0.577 | G40: =Budget!R199 -Budget!Q199 -> 0.16585011 | H40: =Budget!Q199 -> 0.405 | I40: =Config!D38 -> 1 | J40: =Config!D38 -> 1 | K40: =Config!M38 -> 1.3 | L40: =Budget!F40 -> 0.4 | M40: =Budget!G40 -> 1.3 | N40: =Budget!I40 -> 0.2 | O40: =Config!N38 -> B3, dry mass = est + 15%, impulse iteration for apogee | R40: =Config!B38 -> 2026_C_PR_B1_CONFIG36 | V40: =Config!N38 -> B3, dry mass = est + 15%, impulse iteration for apogee
B41: ISP | C41: =Config!B39 -> 2026_C_PR_B1_CONFIG37 | D41: 5.21 | E41: =Budget!R147 - Budget!L147 - Budget!M147 - Budget!Q147 -> 11.456632 | F41: =Budget!Q147 -> 0.577 | G41: =Budget!R200 -Budget!Q200 -> 8.1874076 | H41: =Budget!Q200 -> 0.405 | I41: =Config!D39 -> 7000 | J41: =Config!D39 -> 7000 | K41: =Config!M39 -> 38850 | L41: =Budget!F41 -> 0.4 | M41: =Budget!G41 -> 5.25 | N41: =Budget!I41 -> 0.2 | O41: =Config!N39 -> B3, dry mass = est, ISP iteration | Q41: ISP | R41: =Config!B39 -> 2026_C_PR_B1_CONFIG37 | S41: 3146 | T41: 3.532 | U41: 31.561 | V41: =Config!N39 -> B3, dry mass = est, ISP iteration
...

Sheet ISP
B2: Nominal Thurst [N] | C2: ISP [s] | D2: core O/F [-] | E2: Mass flow tot core [kg/s] | F2: Mass flow ox [kg/s] | G2: Mass flow fuel core [kg/s] | H2: Mass flow fuel [kg/s] | I2: Total impulse [Ns]
B3: 6500 | C3: 200 | D3: 1.5 | E3: =B3/(C3*9.81) -> 3.312946 | F3: =E3/(1+1/D3) -> 1.9877676 | G3: =E3 / (1 +D3 ) -> 1.3251784 | H3: =1.075*G3 -> 1.4245668
B4: 6500 | C4: 201 | D4: 1.5 | E4: =B4/(C4*9.81) -> 3.2964637 | F4: =E4/(1+1/D4) -> 1.9778782 | G4: =E4 / (1 +D4 ) -> 1.3185855 | H4: =1.075*G4 -> 1.4174794
B5: 6500 | C5: 202 | D5: 1.5 | E5: =B5/(C5*9.81) -> 3.2801445 | F5: =E5/(1+1/D5) -> 1.9680867 | G5: =E5 / (1 +D5 ) -> 1.3120578 | H5: =1.075*G5 -> 1.4104621
B6: 6500 | C6: 203 | D6: 1.5 | E6: =B6/(C6*9.81) -> 3.2639862 | F6: =E6/(1+1/D6) -> 1.9583917 | G6: =E6 / (1 +D6 ) -> 1.3055945 | H6: =1.075*G6 -> 1.4035141
B7: 6500 | C7: 204 | D7: 1.5 | E7: =B7/(C7*9.81) -> 3.2479862 | F7: =E7/(1+1/D7) -> 1.9487917 | G7: =E7 / (1 +D7 ) -> 1.2991945 | H7: =1.075*G7 -> 1.3966341
B8: 6500 | C8: 205 | D8: 1.5 | E8: =B8/(C8*9.81) -> 3.2321424 | F8: =E8/(1+1/D8) -> 1.9392854 | G8: =E8 / (1 +D8 ) -> 1.292857 | H8: =1.075*G8 -> 1.3898212
B9: 6500 | C9: 206 | D9: 1.5 | E9: =B9/(C9*9.81) -> 3.2164524 | F9: =E9/(1+1/D9) -> 1.9298714 | G9: =E9 / (1 +D9 ) -> 1.286581 | H9: =1.075*G9 -> 1.3830745
B10: 6500 | C10: 207 | D10: 1.5 | E10: =B10/(C10*9.81) -> 3.200914 | F10: =E10/(1+1/D10) -> 1.9205484 | G10: =E10 / (1 +D10 ) -> 1.2803656 | H10: =1.075*G10 -> 1.376393
B11: 6500 | C11: 208 | D11: 1.5 | E11: =B11/(C11*9.81) -> 3.185525 | F11: =E11/(1+1/D11) -> 1.911315 | G11: =E11 / (1 +D11 ) -> 1.27421 | H11: =1.075*G11 -> 1.3697757
B12: 6500 | C12: 209 | D12: 1.5 | E12: =B12/(C12*9.81) -> 3.1702832 | F12: =E12/(1+1/D12) -> 1.9021699 | G12: =E12 / (1 +D12 ) -> 1.2681133 | H12: =1.075*G12 -> 1.3632218
B13: 6500 | C13: 210 | D13: 1.5 | E13: =B13/(C13*9.81) -> 3.1551866 | F13: =E13/(1+1/D13) -> 1.893112 | G13: =E13 / (1 +D13 ) -> 1.2620747 | H13: =1.075*G13 -> 1.3567303
B14: 6500 | C14: 211 | D14: 1.5 | E14: =B14/(C14*9.81) -> 3.1402332 | F14: =E14/(1+1/D14) -> 1.8841399 | G14: =E14 / (1 +D14 ) -> 1.2560933 | H14: =1.075*G14 -> 1.3503003
... B63: 6500 | C63: 260 | D63: 1.5 | E63: =B63/(C63*9.81) -> 2.54842 | F63: =E63/(1+1/D63) -> 1.529052 | G63: =E63 / (1 +D63 ) -> 1.019368 | H63: =1.075*G63 -> 1.0958206
