Workbook

Sheet Config
B2: Configurations | D2: Dry mass [kg] | E2: Nominal Thurst [N] | F2: ISP [s] | G2: core O/F [-] | H2: Mass flow tot core [kg/s] | I2: Mass flow ox [kg/s] | J2: Mass flow fuel core [kg/s] | K2: Ramp up time [s] | L2: Ramp down time [s] | M2: Total impulse burn [Ns] | N2: Total impulse [Ns] | O2: Description
B3: Firehorn 1 | D3: 84.4 | E3: 6308 | F3: 198 | G3: 1.463 | H3: 3.248 | I3: 1.925 | J3: 1.306 | K3: 0.361 | L3: 0.171 | N3: 36167 | O3: B1 flight configuration of FH1 for reference
B4: THRUST1 | C4: 2026_C_PR_B3_CONFIG1 | D4: 95.66 | E4: 5000 | F4: 240 | G4: 1.5 | H4: =E4/(F4*9.81) -> 2.1236833 | I4: =H4/(1+1/G4) -> 1.27421 | J4: =H4 / (1 +G4 ) -> 0.84947333 | K4: 0.4 | L4: 0.2 | N4: =M4 + K4*E4/2 + L4*E4/2 -> 1500 | O4: B3, dry mass = est, thrust iteration for exit velocity
C5: 2025_C_PR_B3_CONFIG2 | D5: 95.66 | E5: 5500 | F5: 240 | G5: 1.5 | H5: =E5/(F5*9.81) -> 2.3360516 | I5: =H5/(1+1/G5) -> 1.401631 | J5: =H5 / (1 +G5 ) -> 0.93442066 | K5: 0.4 | L5: 0.2 | N5: =M5 + K5*E5/2 + L5*E5/2 -> 1650 | O5: B3, dry mass = est, thrust iteration for exit velocity
C6: 2026_C_PR_B3_CONFIG3 | D6: 95.66 | E6: 6000 | F6: 240 | G6: 1.5 | H6: =E6/(F6*9.81) -> 2.54842 | I6: =H6/(1+1/G6) -> 1.529052 | J6: =H6 / (1 +G6 ) -> 1.019368 | K6: 0.4 | L6: 0.2 | N6: =M6 + K6*E6/2 + L6*E6/2 -> 1800 | O6: B3, dry mass = est, thrust iteration for exit velocity
C7: 2025_C_PR_B3_CONFIG4 | D7: 95.66 | E7: 6500 | F7: 240 | G7: 1.5 | H7: =E7/(F7*9.81) -> 2.7607883 | I7: =H7/(1+1/G7) -> 1.656473 | J7: =H7 / (1 +G7 ) -> 1.1043153 | K7: 0.4 | L7: 0.2 | M7: 36000 | N7: =M7 + K7*E7/2 + L7*E7/2 -> 37950 | O7: B3, dry mass = est, thrust iteration for exit velocity
C8: 2026_C_PR_B3_CONFIG5 | D8: 95.66 | E8: 7000 | F8: 240 | G8: 1.5 | H8: =E8/(F8*9.81) -> 2.9731566 | I8: =H8/(1+1/G8) -> 1.783894 | J8: =H8 / (1 +G8 ) -> 1.1892627 | K8: 0.4 | L8: 0.2 | M8: 36000 | N8: =M8 + K8*E8/2 + L8*E8/2 -> 38100 | O8: B3, dry mass = est, thrust iteration for exit velocity
C9: 2025_C_PR_B3_CONFIG6 | D9: 95.66 | E9: 7500 | F9: 240 | G9: 1.5 | H9: =E9/(F9*9.81) -> 3.185525 | I9: =H9/(1+1/G9) -> 1.911315 | J9: =H9 / (1 +G9 ) -> 1.27421 | K9: 0.4 | L9: 0.2 | N9: =M9 + K9*E9/2 + L9*E9/2 -> 2250 | O9: B3, dry mass = est, thrust iteration for exit velocity
C10: 2026_C_PR_B3_CONFIG7 | D10: 95.66 | E10: 1 | F10: 240 | G10: 1.5 | H10: =E10/(F10*9.81) -> 0.00042473666 | I10: =H10/(1+1/G10) -> 0.000254842 | J10: =H10 / (1 +G10 ) -> 0.00016989467 | K10: 0.4 | L10: 0.2 | N10: =M10 + K10*E10/2 + L10*E10/2 -> 0.3 | O10: B3, dry mass = est, thrust iteration for exit velocity
C11: 2025_C_PR_B3_CONFIG8 | D11: 95.66 | E11: 1 | F11: 240 | G11: 1.5 | H11: =E11/(F11*9.81) -> 0.00042473666 | I11: =H11/(1+1/G11) -> 0.000254842 | J11: =H11 / (1 +G11 ) -> 0.00016989467 | K11: 0.4 | L11: 0.2 | N11: =M11 + K11*E11/2 + L11*E11/2 -> 0.3 | O11: B3, dry mass = est, thrust iteration for exit velocity
C12: 2026_C_PR_B3_CONFIG9 | D12: 95.66 | E12: 1 | F12: 240 | G12: 1.5 | H12: =E12/(F12*9.81) -> 0.00042473666 | I12: =H12/(1+1/G12) -> 0.000254842 | J12: =H12 / (1 +G12 ) -> 0.00016989467 | K12: 0.4 | L12: 0.2 | N12: =M12 + K12*E12/2 + L12*E12/2 -> 0.3 | O12: B3, dry mass = est, thrust iteration for exit velocity
C13: 2026_C_PR_B3_CONFIG10 | D13: 95.66 | E13: 1 | F13: 240 | G13: 1.5 | H13: =E13/(F13*9.81) -> 0.00042473666 | I13: =H13/(1+1/G13) -> 0.000254842 | J13: =H13 / (1 +G13 ) -> 0.00016989467 | K13: 0.4 | L13: 0.2 | N13: =M13 + K13*E13/2 + L13*E13/2 -> 0.3 | O13: B3, dry mass = est, thrust iteration for exit velocity
C14: 2026_C_PR_B3_CONFIG11 | D14: 95.66 | E14: 1 | F14: 240 | G14: 1.5 | H14: =E14/(F14*9.81) -> 0.00042473666 | I14: =H14/(1+1/G14) -> 0.000254842 | J14: =H14 / (1 +G14 ) -> 0.00016989467 | K14: 0.4 | L14: 0.2 | N14: =M14 + K14*E14/2 + L14*E14/2 -> 0.3 | O14: B3, dry mass = est, thrust iteration for exit velocity
C15: 2026_C_PR_B3_CONFIG12 | D15: 95.66 | E15: 1 | F15: 240 | G15: 1.5 | H15: =E15/(F15*9.81) -> 0.00042473666 | I15: =H15/(1+1/G15) -> 0.000254842 | J15: =H15 / (1 +G15 ) -> 0.00016989467 | K15: 0.4 | L15: 0.2 | N15: =M15 + K15*E15/2 + L15*E15/2 -> 0.3 | O15: B3, dry mass = est, thrust iteration for exit velocity
B16: THRUST2 | C16: 2026_C_PR_B3_CONFIG13 | D16: 107.28 | E16: 5000 | F16: 240 | G16: 1.5 | H16: =E16/(F16*9.81) -> 2.1236833 | I16: =H16/(1+1/G16) -> 1.27421 | J16: =H16 / (1 +G16 ) -> 0.84947333 | K16: 0.4 | L16: 0.2 | N16: =M16 + K16*E16/2 + L16*E16/2 -> 1500 | O16: B3, dry mass = est + 15%, thrust iteration for exit velocity
C17: 2026_C_PR_B3_CONFIG14 | D17: 107.28 | E17: 5500 | F17: 240 | G17: 1.5 | H17: =E17/(F17*9.81) -> 2.3360516 | I17: =H17/(1+1/G17) -> 1.401631 | J17: =H17 / (1 +G17 ) -> 0.93442066 | K17: 0.4 | L17: 0.2 | N17: =M17 + K17*E17/2 + L17*E17/2 -> 1650 | O17: B3, dry mass = est + 15%, thrust iteration for exit velocity
C18: 2026_C_PR_B3_CONFIG15 | D18: 107.28 | E18: 6000 | F18: 240 | G18: 1.5 | H18: =E18/(F18*9.81) -> 2.54842 | I18: =H18/(1+1/G18) -> 1.529052 | J18: =H18 / (1 +G18 ) -> 1.019368 | K18: 0.4 | L18: 0.2 | N18: =M18 + K18*E18/2 + L18*E18/2 -> 1800 | O18: B3, dry mass = est + 15%, thrust iteration for exit velocity
C19: 2026_C_PR_B3_CONFIG16 | D19: 107.28 | E19: 6500 | F19: 240 | G19: 1.5 | H19: =E19/(F19*9.81) -> 2.7607883 | I19: =H19/(1+1/G19) -> 1.656473 | J19: =H19 / (1 +G19 ) -> 1.1043153 | K19: 0.4 | L19: 0.2 | N19: =M19 + K19*E19/2 + L19*E19/2 -> 1950 | O19: B3, dry mass = est + 15%, thrust iteration for exit velocity
C20: 2026_C_PR_B3_CONFIG17 | D20: 107.28 | E20: 7000 | F20: 240 | G20: 1.5 | H20: =E20/(F20*9.81) -> 2.9731566 | I20: =H20/(1+1/G20) -> 1.783894 | J20: =H20 / (1 +G20 ) -> 1.1892627 | K20: 0.4 | L20: 0.2 | N20: =M20 + K20*E20/2 + L20*E20/2 -> 2100 | O20: B3, dry mass = est + 15%, thrust iteration for exit velocity
C21: 2026_C_PR_B3_CONFIG18 | D21: 107.28 | E21: 7500 | F21: 240 | G21: 1.5 | H21: =E21/(F21*9.81) -> 3.185525 | I21: =H21/(1+1/G21) -> 1.911315 | J21: =H21 / (1 +G21 ) -> 1.27421 | K21: 0.4 | L21: 0.2 | M21: 36000 | N21: =M21 + K21*E21/2 + L21*E21/2 -> 38250 | O21: B3, dry mass = est + 15%, thrust iteration for exit velocity
C22: 2026_C_PR_B3_CONFIG19 | D22: 107.28 | E22: 8000 | F22: 240 | G22: 1.5 | H22: =E22/(F22*9.81) -> 3.3978933 | I22: =H22/(1+1/G22) -> 2.038736 | J22: =H22 / (1 +G22 ) -> 1.3591573 | K22: 0.4 | L22: 0.2 | M22: 36000 | N22: =M22 + K22*E22/2 + L22*E22/2 -> 38400 | O22: B3, dry mass = est + 15%, thrust iteration for exit velocity
C23: 2026_C_PR_B3_CONFIG20 | D23: 107.28 | E23: 1 | F23: 240 | G23: 1.5 | H23: =E23/(F23*9.81) -> 0.00042473666 | I23: =H23/(1+1/G23) -> 0.000254842 | J23: =H23 / (1 +G23 ) -> 0.00016989467 | K23: 0.4 | L23: 0.2 | N23: =M23 + K23*E23/2 + L23*E23/2 -> 0.3 | O23: B3, dry mass = est + 15%, thrust iteration for exit velocity
C24: 2026_C_PR_B3_CONFIG21 | D24: 107.28 | E24: 1 | F24: 240 | G24: 1.5 | H24: =E24/(F24*9.81) -> 0.00042473666 | I24: =H24/(1+1/G24) -> 0.000254842 | J24: =H24 / (1 +G24 ) -> 0.00016989467 | K24: 0.4 | L24: 0.2 | N24: =M24 + K24*E24/2 + L24*E24/2 -> 0.3 | O24: B3, dry mass = est + 15%, thrust iteration for exit velocity
C25: 2026_C_PR_B3_CONFIG22 | D25: 107.28 | E25: 1 | F25: 240 | G25: 1.5 | H25: =E25/(F25*9.81) -> 0.00042473666 | I25: =H25/(1+1/G25) -> 0.000254842 | J25: =H25 / (1 +G25 ) -> 0.00016989467 | K25: 0.4 | L25: 0.2 | N25: =M25 + K25*E25/2 + L25*E25/2 -> 0.3 | O25: B3, dry mass = est + 15%, thrust iteration for exit velocity
C26: 2026_C_PR_B3_CONFIG23 | D26: 107.28 | E26: 1 | F26: 240 | G26: 1.5 | H26: =E26/(F26*9.81) -> 0.00042473666 | I26: =H26/(1+1/G26) -> 0.000254842 | J26: =H26 / (1 +G26 ) -> 0.00016989467 | K26: 0.4 | L26: 0.2 | N26: =M26 + K26*E26/2 + L26*E26/2 -> 0.3 | O26: B3, dry mass = est + 15%, thrust iteration for exit velocity
C27: 2026_C_PR_B3_CONFIG24 | D27: 107.28 | E27: 1 | F27: 240 | G27: 1.5 | H27: =E27/(F27*9.81) -> 0.00042473666 | I27: =H27/(1+1/G27) -> 0.000254842 | J27: =H27 / (1 +G27 ) -> 0.00016989467 | K27: 0.4 | L27: 0.2 | N27: =M27 + K27*E27/2 + L27*E27/2 -> 0.3 | O27: B3, dry mass = est + 15%, thrust iteration for exit velocity
B28: IMPULSE1 | C28: 2026_C_PR_B3_CONFIG25 | D28: 95.66 | E28: 7000 | F28: 240 | G28: 1.5 | H28: =E28/(F28*9.81) -> 2.9731566 | I28: =H28/(1+1/G28) -> 1.783894 | J28: =H28 / (1 +G28 ) -> 1.1892627 | K28: 0.4 | L28: 0.2 | M28: 35000 | N28: =M28 + K28*E28/2 + L28*E28/2 -> 37100 | O28: B3, dry mass = est, impulse iteration for apogee
C29: 2026_C_PR_B3_CONFIG26 | D29: 95.66 | E29: 7000 | F29: 240 | G29: 1.5 | H29: =E29/(F29*9.81) -> 2.9731566 | I29: =H29/(1+1/G29) -> 1.783894 | J29: =H29 / (1 +G29 ) -> 1.1892627 | K29: 0.4 | L29: 0.2 | M29: 37500 | N29: =M29 + K29*E29/2 + L29*E29/2 -> 39600 | O29: B3, dry mass = est, impulse iteration for apogee
C30: 2026_C_PR_B3_CONFIG27 | D30: 95.66 | E30: 7000 | F30: 240 | G30: 1.5 | H30: =E30/(F30*9.81) -> 2.9731566 | I30: =H30/(1+1/G30) -> 1.783894 | J30: =H30 / (1 +G30 ) -> 1.1892627 | K30: 0.4 | L30: 0.2 | M30: 36000 | N30: =M30 + K30*E30/2 + L30*E30/2 -> 38100 | O30: B3, dry mass = est, impulse iteration for apogee
C31: 2026_C_PR_B3_CONFIG28 | D31: 95.66 | E31: 7000 | F31: 240 | G31: 1.5 | H31: =E31/(F31*9.81) -> 2.9731566 | I31: =H31/(1+1/G31) -> 1.783894 | J31: =H31 / (1 +G31 ) -> 1.1892627 | K31: 0.4 | L31: 0.2 | M31: 36500 | N31: =M31 + K31*E31/2 + L31*E31/2 -> 38600 | O31: B3, dry mass = est, impulse iteration for apogee
C32: 2026_C_PR_B3_CONFIG29 | D32: 95.66 | E32: 7000 | F32: 240 | G32: 1.5 | H32: =E32/(F32*9.81) -> 2.9731566 | I32: =H32/(1+1/G32) -> 1.783894 | J32: =H32 / (1 +G32 ) -> 1.1892627 | K32: 0.4 | L32: 0.2 | M32: 36750 | N32: =M32 + K32*E32/2 + L32*E32/2 -> 38850 | O32: B3, dry mass = est, impulse iteration for apogee
C33: 2026_C_PR_B3_CONFIG30 | D33: 95.66 | E33: 1 | F33: 240 | G33: 1.5 | H33: =E33/(F33*9.81) -> 0.00042473666 | I33: =H33/(1+1/G33) -> 0.000254842 | J33: =H33 / (1 +G33 ) -> 0.00016989467 | K33: 0.4 | L33: 0.2 | M33: 1 | N33: =M33 + K33*E33/2 + L33*E33/2 -> 1.3 | O33: B3, dry mass = est, impulse iteration for apogee
B34: IMPULSE2 | C34: 2026_C_PR_B3_CONFIG31 | D34: 107.28 | E34: 8000 | F34: 240 | G34: 1.5 | H34: =E34/(F34*9.81) -> 3.3978933 | I34: =H34/(1+1/G34) -> 2.038736 | J34: =H34 / (1 +G34 ) -> 1.3591573 | K34: 0.4 | L34: 0.2 | M34: 37000 | N34: =M34 + K34*E34/2 + L34*E34/2 -> 39400 | O34: B3, dry mass = est + 15%, impulse iteration for apogee
C35: 2026_C_PR_B3_CONFIG32 | D35: 107.28 | E35: 8000 | F35: 240 | G35: 1.5 | H35: =E35/(F35*9.81) -> 3.3978933 | I35: =H35/(1+1/G35) -> 2.038736 | J35: =H35 / (1 +G35 ) -> 1.3591573 | K35: 0.4 | L35: 0.2 | M35: 37500 | N35: =M35 + K35*E35/2 + L35*E35/2 -> 39900 | O35: B3, dry mass = est + 15%, impulse iteration for apogee
C36: 2026_C_PR_B3_CONFIG33 | D36: 107.28 | E36: 8000 | F36: 240 | G36: 1.5 | H36: =E36/(F36*9.81) -> 3.3978933 | I36: =H36/(1+1/G36) -> 2.038736 | J36: =H36 / (1 +G36 ) -> 1.3591573 | K36: 0.4 | L36: 0.2 | M36: 1 | N36: =M36 + K36*E36/2 + L36*E36/2 -> 2401 | O36: B3, dry mass = est + 15%, impulse iteration for apogee
C37: 2026_C_PR_B3_CONFIG34 | D37: 107.28 | E37: 8000 | F37: 240 | G37: 1.5 | H37: =E37/(F37*9.81) -> 3.3978933 | I37: =H37/(1+1/G37) -> 2.038736 | J37: =H37 / (1 +G37 ) -> 1.3591573 | K37: 0.4 | L37: 0.2 | M37: 1 | N37: =M37 + K37*E37/2 + L37*E37/2 -> 2401 | O37: B3, dry mass = est + 15%, impulse iteration for apogee
C38: 2026_C_PR_B1_CONFIG35 | D38: 107.28 | E38: 1 | F38: 240 | G38: 1.5 | H38: =E38/(F38*9.81) -> 0.00042473666 | I38: =H38/(1+1/G38) -> 0.000254842 | J38: =H38 / (1 +G38 ) -> 0.00016989467 | K38: 0.4 | L38: 0.2 | M38: 1 | N38: =M38 + K38*E38/2 + L38*E38/2 -> 1.3 | O38: B3, dry mass = est + 15%, impulse iteration for apogee
C39: 2026_C_PR_B1_CONFIG36 | D39: 107.28 | E39: 1 | F39: 240 | G39: 1.5 | H39: =E39/(F39*9.81) -> 0.00042473666 | I39: =H39/(1+1/G39) -> 0.000254842 | J39: =H39 / (1 +G39 ) -> 0.00016989467 | K39: 0.4 | L39: 0.2 | M39: 1 | N39: =M39 + K39*E39/2 + L39*E39/2 -> 1.3 | O39: B3, dry mass = est + 15%, impulse iteration for apogee
B40: ISP | C40: 2026_C_PR_B1_CONFIG37 | D40: 95.66 | E40: 7000 | F40: 200 | G40: 1.5 | H40: =E40/(F40*9.81) -> 3.567788 | I40: =H40/(1+1/G40) -> 2.1406728 | J40: =H40 / (1 +G40 ) -> 1.4271152 | K40: 0.4 | L40: 0.2 | M40: 36750 | N40: =M40 + K40*E40/2 + L40*E40/2 -> 38850 | O40: B3, dry mass = est, ISP iteration
C41: 2026_C_PR_B1_CONFIG38 | D41: 95.66 | E41: 7000 | F41: 205 | G41: 1.5 | H41: =E41/(F41*9.81) -> 3.4807688 | I41: =H41/(1+1/G41) -> 2.0884613 | J41: =H41 / (1 +G41 ) -> 1.3923075 | K41: 0.4 | L41: 0.2 | M41: 36750 | N41: =M41 + K41*E41/2 + L41*E41/2 -> 38850 | O41: B3, dry mass = est, ISP iteration
...

Sheet Budget
B2: Timings | D2: Hold | E2: Prechill | F2: Ignition | G2: Ramp Up | H2: Burn | I2: Cutoff | J2: Ramp Down
D3: duration | E3: duration | F3: ignition_delay | G3: ramp_up_duration | H3: nominal_duration | I3: delay | J3: ramp_down_duration
B4: Firehorn 1 | D4: 300 | E4: 0.2 | F4: -0.05 | G4: 0.153 | H4: 6.69 | I4: 0.025 | J4: 0.247
D5: =549+90 -> 639 | E5: 0.2 | F5: -0.05 | G5: 0.361 | H5: 1.082 | I5: 0.025 | J5: 0.171
B6: THRUST1 | C6: =Config!C4 -> 2026_C_PR_B3_CONFIG1 | D6: 300 | E6: 0.2 | F6: -0.05 | G6: =Config!K4 -> 0.4 | H6: =Config!N4/Config!E4 -> 0.3 | I6: 0.025 | J6: =Config!L4 -> 0.2
C7: =Config!C5 -> 2025_C_PR_B3_CONFIG2 | D7: 300 | E7: 0.2 | F7: -0.05 | G7: =Config!K5 -> 0.4 | H7: =Config!N5/Config!E5 -> 0.3 | I7: 0.025 | J7: =Config!L5 -> 0.2
C8: =Config!C6 -> 2026_C_PR_B3_CONFIG3 | D8: 300 | E8: 0.2 | F8: -0.05 | G8: =Config!K6 -> 0.4 | H8: =Config!N6/Config!E6 -> 0.3 | I8: 0.025 | J8: =Config!L6 -> 0.2
C9: =Config!C7 -> 2025_C_PR_B3_CONFIG4 | D9: 300 | E9: 0.2 | F9: -0.05 | G9: =Config!K7 -> 0.4 | H9: =Config!N7/Config!E7 -> 5.8384615 | I9: 0.025 | J9: =Config!L7 -> 0.2
C10: =Config!C8 -> 2026_C_PR_B3_CONFIG5 | D10: 300 | E10: 0.2 | F10: -0.05 | G10: =Config!K8 -> 0.4 | H10: =Config!N8/Config!E8 -> 5.4428571 | I10: 0.025 | J10: =Config!L8 -> 0.2
C11: =Config!C9 -> 2025_C_PR_B3_CONFIG6 | D11: 300 | E11: 0.2 | F11: -0.05 | G11: =Config!K9 -> 0.4 | H11: =Config!N9/Config!E9 -> 0.3 | I11: 0.025 | J11: =Config!L9 -> 0.2
C12: =Config!C10 -> 2026_C_PR_B3_CONFIG7 | D12: 300 | E12: 0.2 | F12: -0.05 | G12: =Config!K10 -> 0.4 | H12: =Config!N10/Config!E10 -> 0.3 | I12: 0.025 | J12: =Config!L10 -> 0.2
C13: =Config!C11 -> 2025_C_PR_B3_CONFIG8 | D13: 300 | E13: 0.2 | F13: -0.05 | G13: =Config!K11 -> 0.4 | H13: =Config!N11/Config!E11 -> 0.3 | I13: 0.025 | J13: =Config!L11 -> 0.2
C14: =Config!C12 -> 2026_C_PR_B3_CONFIG9 | D14: 300 | E14: 0.2 | F14: -0.05 | G14: =Config!K12 -> 0.4 | H14: =Config!N12/Config!E12 -> 0.3 | I14: 0.025 | J14: =Config!L12 -> 0.2
C15: =Config!C13 -> 2026_C_PR_B3_CONFIG10 | D15: 300 | E15: 0.2 | F15: -0.05 | G15: =Config!K13 -> 0.4 | H15: =Config!N13/Config!E13 -> 0.3 | I15: 0.025 | J15: =Config!L13 -> 0.2
C16: =Config!C14 -> 2026_C_PR_B3_CONFIG11 | D16: 300 | E16: 0.2 | F16: -0.05 | G16: =Config!K14 -> 0.4 | H16: =Config!N14/Config!E14 -> 0.3 | I16: 0.025 | J16: =Config!L14 -> 0.2
C17: =Config!C15 -> 2026_C_PR_B3_CONFIG12 | D17: 300 | E17: 0.2 | F17: -0.05 | G17: =Config!K15 -> 0.4 | H17: =Config!N15/Config!E15 -> 0.3 | I17: 0.025 | J17: =Config!L15 -> 0.2
B18: THRUST2 | C18: =Config!C16 -> 2026_C_PR_B3_CONFIG13 | D18: 300 | E18: 0.2 | F18: -0.05 | G18: =Config!K16 -> 0.4 | H18: =Config!N16/Config!E16 -> 0.3 | I18: 0.025 | J18: =Config!L16 -> 0.2
C19: =Config!C17 -> 2026_C_PR_B3_CONFIG14 | D19: 300 | E19: 0.2 | F19: -0.05 | G19: =Config!K17 -> 0.4 | H19: =Config!N17/Config!E17 -> 0.3 | I19: 0.025 | J19: =Config!L17 -> 0.2
C20: =Config!C18 -> 2026_C_PR_B3_CONFIG15 | D20: 300 | E20: 0.2 | F20: -0.05 | G20: =Config!K18 -> 0.4 | H20: =Config!N18/Config!E18 -> 0.3 | I20: 0.025 | J20: =Config!L18 -> 0.2
C21: =Config!C19 -> 2026_C_PR_B3_CONFIG16 | D21: 300 | E21: 0.2 | F21: -0.05 | G21: =Config!K19 -> 0.4 | H21: =Config!N19/Config!E19 -> 0.3 | I21: 0.025 | J21: =Config!L19 -> 0.2
C22: =Config!C20 -> 2026_C_PR_B3_CONFIG17 | D22: 300 | E22: 0.2 | F22: -0.05 | G22: =Config!K20 -> 0.4 | H22: =Config!N20/Config!E20 -> 0.3 | I22: 0.025 | J22: =Config!L20 -> 0.2
C23: =Config!C21 -> 2026_C_PR_B3_CONFIG18 | D23: 300 | E23: 0.2 | F23: -0.05 | G23: =Config!K21 -> 0.4 | H23: =Config!N21/Config!E21 -> 5.1 | I23: 0.025 | J23: =Config!L21 -> 0.2
C24: =Config!C22 -> 2026_C_PR_B3_CONFIG19 | D24: 300 | E24: 0.2 | F24: -0.05 | G24: =Config!K22 -> 0.4 | H24: =Config!N22/Config!E22 -> 4.8 | I24: 0.025 | J24: =Config!L22 -> 0.2
C25: =Config!C23 -> 2026_C_PR_B3_CONFIG20 | D25: 300 | E25: 0.2 | F25: -0.05 | G25: =Config!K23 -> 0.4 | H25: =Config!N23/Config!E23 -> 0.3 | I25: 0.025 | J25: =Config!L23 -> 0.2
C26: =Config!C24 -> 2026_C_PR_B3_CONFIG21 | D26: 300 | E26: 0.2 | F26: -0.05 | G26: =Config!K24 -> 0.4 | H26: =Config!N24/Config!E24 -> 0.3 | I26: 0.025 | J26: =Config!L24 -> 0.2
C27: =Config!C25 -> 2026_C_PR_B3_CONFIG22 | D27: 300 | E27: 0.2 | F27: -0.05 | G27: =Config!K25 -> 0.4 | H27: =Config!N25/Config!E25 -> 0.3 | I27: 0.025 | J27: =Config!L25 -> 0.2
C28: =Config!C26 -> 2026_C_PR_B3_CONFIG23 | D28: 300 | E28: 0.2 | F28: -0.05 | G28: =Config!K26 -> 0.4 | H28: =Config!N26/Config!E26 -> 0.3 | I28: 0.025 | J28: =Config!L26 -> 0.2
C29: =Config!C27 -> 2026_C_PR_B3_CONFIG24 | D29: 300 | E29: 0.2 | F29: -0.05 | G29: =Config!K27 -> 0.4 | H29: =Config!N27/Config!E27 -> 0.3 | I29: 0.025 | J29: =Config!L27 -> 0.2
B30: IMPULSE1 | C30: =Config!C28 -> 2026_C_PR_B3_CONFIG25 | D30: 300 | E30: 0.2 | F30: -0.05 | G30: =Config!K28 -> 0.4 | H30: =Config!N28/Config!E28 -> 5.3 | I30: 0.025 | J30: =Config!L28 -> 0.2
C31: =Config!C29 -> 2026_C_PR_B3_CONFIG26 | D31: 300 | E31: 0.2 | F31: -0.05 | G31: =Config!K29 -> 0.4 | H31: =Config!N29/Config!E29 -> 5.6571429 | I31: 0.025 | J31: =Config!L29 -> 0.2
C32: =Config!C30 -> 2026_C_PR_B3_CONFIG27 | D32: 300 | E32: 0.2 | F32: -0.05 | G32: =Config!K30 -> 0.4 | H32: =Config!N30/Config!E30 -> 5.4428571 | I32: 0.025 | J32: =Config!L30 -> 0.2
C33: =Config!C31 -> 2026_C_PR_B3_CONFIG28 | D33: 300 | E33: 0.2 | F33: -0.05 | G33: =Config!K31 -> 0.4 | H33: =Config!N31/Config!E31 -> 5.5142857 | I33: 0.025 | J33: =Config!L31 -> 0.2
C34: =Config!C32 -> 2026_C_PR_B3_CONFIG29 | D34: 300 | E34: 0.2 | F34: -0.05 | G34: =Config!K32 -> 0.4 | H34: =Config!N32/Config!E32 -> 5.55 | I34: 0.025 | J34: =Config!L32 -> 0.2
C35: =Config!C33 -> 2026_C_PR_B3_CONFIG30 | D35: 300 | E35: 0.2 | F35: -0.05 | G35: =Config!K33 -> 0.4 | H35: =Config!N33/Config!E33 -> 1.3 | I35: 0.025 | J35: =Config!L33 -> 0.2
B36: IMPULSE2 | C36: =Config!C34 -> 2026_C_PR_B3_CONFIG31 | D36: 300 | E36: 0.2 | F36: -0.05 | G36: =Config!K34 -> 0.4 | H36: =Config!N34/Config!E34 -> 4.925 | I36: 0.025 | J36: =Config!L34 -> 0.2
C37: =Config!C35 -> 2026_C_PR_B3_CONFIG32 | D37: 300 | E37: 0.2 | F37: -0.05 | G37: =Config!K35 -> 0.4 | H37: =Config!N35/Config!E35 -> 4.9875 | I37: 0.025 | J37: =Config!L35 -> 0.2
C38: =Config!C36 -> 2026_C_PR_B3_CONFIG33 | D38: 300 | E38: 0.2 | F38: -0.05 | G38: =Config!K36 -> 0.4 | H38: =Config!N36/Config!E36 -> 0.300125 | I38: 0.025 | J38: =Config!L36 -> 0.2
C39: =Config!C37 -> 2026_C_PR_B3_CONFIG34 | D39: 300 | E39: 0.2 | F39: -0.05 | G39: =Config!K37 -> 0.4 | H39: =Config!N37/Config!E37 -> 0.300125 | I39: 0.025 | J39: =Config!L37 -> 0.2
C40: =Config!C38 -> 2026_C_PR_B1_CONFIG35 | D40: 639 | E40: 0.2 | F40: -0.05 | G40: =Config!K38 -> 0.4 | H40: =Config!N38/Config!E38 -> 1.3 | I40: 0.025 | J40: =Config!L38 -> 0.2
C41: =Config!C39 -> 2026_C_PR_B1_CONFIG36 | D41: 639 | E41: 0.2 | F41: -0.05 | G41: =Config!K39 -> 0.4 | H41: =Config!N39/Config!E39 -> 1.3 | I41: 0.025 | J41: =Config!L39 -> 0.2
...

Sheet Simulations
B2: Simulations inputs | D2: N2 | E2: Oxidizer | G2: Fuel | I2: Thrust [N] | K2: Total Impulse | L2: Timing [s] | O2: Description | Q2: Simulations outputs | S2: Apogee [m] | T2: Rail exit static margin [c] | U2: Rail exit velocity [m/s] | V2: Description
D3: Mass total [kg] | E3: Mass total [kg] | F3: Mass remaining [kg] | G3: Mass total [kg] | H3: Mass remaining [kg] | I3: Full | J3: Derated | L3: Ramp up | M3: Burn time | N3: Ramp down
B4: Firehorn 1 | D4: =Budget!F57 -> 2.605 | E4: =Budget!S110 -> 13.647 | F4: =Budget!R110 -> 2.67 | G4: =Budget!S163 -> 9.639 | H4: =Budget!R163 -> 0.527 | I4: =Config!E3 -> 6308 | J4: ND | K4: =Config!N3 -> 36167 | L4: =Budget!G5 -> 0.361 | M4: =Budget!H4 -> 6.69 | N4: =Budget!J5 -> 0.171 | O4: B1 flight configuration of FH1 for reference (no simulation needed) | Q4: Firehorn 1 | S4: / | T4: / | U4: / | V4: B1 flight configuration of FH1 for reference (no simulation needed)
B5: THRUST1 | C5: 2026_C_PR_B3_CONFIG1 | D5: =Budget!F59 -> 5.21037 | E5: =Budget!S112 - Budget!M112 - Budget!N112 - Budget!R112 -> 0.600363 | F5: =Budget!R112 -> 0.577 | G5: =Budget!S165 -Budget!R165 -> 0.29678474 | H5: =Budget!R165 -> 0.405 | I5: =Config!E4 -> 5000 | J5: =Config!E4 -> 5000 | K5: =Config!N4 -> 1500 | L5: =Budget!G6 -> 0.4 | M5: =Budget!H6 -> 0.3 | N5: =Budget!J6 -> 0.2 | O5: =Config!O4 -> B3, dry mass = est, thrust iteration for exit velocity | Q5: THRUST1 | R5: =Config!C4 -> 2026_C_PR_B3_CONFIG1 | V5: =Config!O4 -> B3, dry mass = est, thrust iteration for exit velocity
C6: 2025_C_PR_B3_CONFIG2 | D6: =Budget!F60 -> 5.21037 | E6: =Budget!S113 - Budget!M113 - Budget!N113 - Budget!R113 -> 0.6385893 | F6: =Budget!R113 -> 0.577 | G6: =Budget!S166 -Budget!R166 -> 0.32646322 | H6: =Budget!R166 -> 0.405 | I6: =Config!E5 -> 5500 | J6: =Config!E5 -> 5500 | K6: =Config!N5 -> 1650 | L6: =Budget!G7 -> 0.4 | M6: =Budget!H7 -> 0.3 | N6: =Budget!J7 -> 0.2 | O6: =Config!O5 -> B3, dry mass = est, thrust iteration for exit velocity | R6: =Config!C5 -> 2025_C_PR_B3_CONFIG2 | V6: =Config!O5 -> B3, dry mass = est, thrust iteration for exit velocity
C7: 2026_C_PR_B3_CONFIG3 | D7: =Budget!F61 -> 5.21037 | E7: =Budget!S114 - Budget!M114 - Budget!N114 - Budget!R114 -> 0.6768156 | F7: =Budget!R114 -> 0.577 | G7: =Budget!S167 -Budget!R167 -> 0.35614169 | H7: =Budget!R167 -> 0.405 | I7: =Config!E6 -> 6000 | J7: =Config!E6 -> 6000 | K7: =Config!N6 -> 1800 | L7: =Budget!G8 -> 0.4 | M7: =Budget!H8 -> 0.3 | N7: =Budget!J8 -> 0.2 | O7: =Config!O6 -> B3, dry mass = est, thrust iteration for exit velocity | R7: =Config!C6 -> 2026_C_PR_B3_CONFIG3 | V7: =Config!O6 -> B3, dry mass = est, thrust iteration for exit velocity
C8: 2025_C_PR_B3_CONFIG4 | D8: =Budget!F62 -> 5.21037 | E8: =Budget!S115 - Budget!M115 - Budget!N115 - Budget!R115 -> 9.8893538 | F8: =Budget!R115 -> 0.577 | G8: =Budget!S168 -Budget!R168 -> 6.9607437 | H8: =Budget!R168 -> 0.405 | I8: =Config!E7 -> 6500 | J8: =Config!E7 -> 6500 | K8: =Config!N7 -> 37950 | L8: =Budget!G9 -> 0.4 | M8: =Budget!H9 -> 5.8384615 | N8: =Budget!J9 -> 0.2 | O8: =Config!O7 -> B3, dry mass = est, thrust iteration for exit velocity | R8: =Config!C7 -> 2025_C_PR_B3_CONFIG4 | S8: 3172 | T8: 3.601 | U8: 30.557 | V8: =Config!O7 -> B3, dry mass = est, thrust iteration for exit velocity
C9: 2026_C_PR_B3_CONFIG5 | D9: =Budget!F63 -> 5.21037 | E9: =Budget!S116 - Budget!M116 - Budget!N116 - Budget!R116 -> 9.9275801 | F9: =Budget!R116 -> 0.577 | G9: =Budget!S169 -Budget!R169 -> 6.9904222 | H9: =Budget!R169 -> 0.405 | I9: =Config!E8 -> 7000 | J9: =Config!E8 -> 7000 | K9: =Config!N8 -> 38100 | L9: =Budget!G10 -> 0.4 | M9: =Budget!H10 -> 5.4428571 | N9: =Budget!J10 -> 0.2 | O9: =Config!O8 -> B3, dry mass = est, thrust iteration for exit velocity | R9: =Config!C8 -> 2026_C_PR_B3_CONFIG5 | S9: 3267 | T9: 3.6 | U9: 31.951 | V9: =Config!O8 -> B3, dry mass = est, thrust iteration for exit velocity
C10: 2025_C_PR_B3_CONFIG6 | D10: =Budget!F64 -> 5.21037 | E10: =Budget!S117 - Budget!M117 - Budget!N117 - Budget!R117 -> 0.7914945 | F10: =Budget!R117 -> 0.577 | G10: =Budget!S170 -Budget!R170 -> 0.44517712 | H10: =Budget!R170 -> 0.405 | I10: =Config!E9 -> 7500 | J10: =Config!E9 -> 7500 | K10: =Config!N9 -> 2250 | L10: =Budget!G11 -> 0.4 | M10: =Budget!H11 -> 0.3 | N10: =Budget!J11 -> 0.2 | O10: =Config!O9 -> B3, dry mass = est, thrust iteration for exit velocity | R10: =Config!C9 -> 2025_C_PR_B3_CONFIG6 | V10: =Config!O9 -> B3, dry mass = est, thrust iteration for exit velocity
C11: 2026_C_PR_B3_CONFIG7 | D11: =Budget!F65 -> 5.21037 | E11: =Budget!S118 - Budget!M118 - Budget!N118 - Budget!R118 -> 0.21817645 | F11: =Budget!R118 -> 0.577 | G11: =Budget!S171 -Budget!R171 -> 5.9356949e-05 | H11: =Budget!R171 -> 0.405 | I11: =Config!E10 -> 1 | J11: =Config!E10 -> 1 | K11: =Config!N10 -> 0.3 | L11: =Budget!G12 -> 0.4 | M11: =Budget!H12 -> 0.3 | N11: =Budget!J12 -> 0.2 | O11: =Config!O10 -> B3, dry mass = est, thrust iteration for exit velocity | R11: =Config!C10 -> 2026_C_PR_B3_CONFIG7 | V11: =Config!O10 -> B3, dry mass = est, thrust iteration for exit velocity
C12: 2025_C_PR_B3_CONFIG8 | D12: =Budget!F66 -> 5.21037 | E12: =Budget!S119 - Budget!M119 - Budget!N119 - Budget!R119 -> 0.21817645 | F12: =Budget!R119 -> 0.577 | G12: =Budget!S172 -Budget!R172 -> 5.9356949e-05 | H12: =Budget!R172 -> 0.405 | I12: =Config!E11 -> 1 | J12: =Config!E11 -> 1 | K12: =Config!N11 -> 0.3 | L12: =Budget!G13 -> 0.4 | M12: =Budget!H13 -> 0.3 | N12: =Budget!J13 -> 0.2 | O12: =Config!O11 -> B3, dry mass = est, thrust iteration for exit velocity | R12: =Config!C11 -> 2025_C_PR_B3_CONFIG8 | V12: =Config!O11 -> B3, dry mass = est, thrust iteration for exit velocity
C13: 2026_C_PR_B3_CONFIG9 | D13: =Budget!F67 -> 5.21037 | E13: =Budget!S120 - Budget!M120 - Budget!N120 - Budget!R120 -> 0.21817645 | F13: =Budget!R120 -> 0.577 | G13: =Budget!S173 -Budget!R173 -> 5.9356949e-05 | H13: =Budget!R173 -> 0.405 | I13: =Config!E12 -> 1 | J13: =Config!E12 -> 1 | K13: =Config!N12 -> 0.3 | L13: =Budget!G14 -> 0.4 | M13: =Budget!H14 -> 0.3 | N13: =Budget!J14 -> 0.2 | O13: =Config!O12 -> B3, dry mass = est, thrust iteration for exit velocity | R13: =Config!C12 -> 2026_C_PR_B3_CONFIG9 | V13: =Config!O12 -> B3, dry mass = est, thrust iteration for exit velocity
C14: 2026_C_PR_B3_CONFIG10 | D14: =Budget!F68 -> 5.21037 | E14: =Budget!S121 - Budget!M121 - Budget!N121 - Budget!R121 -> 0.21817645 | F14: =Budget!R121 -> 0.577 | G14: =Budget!S174 -Budget!R174 -> 5.9356949e-05 | H14: =Budget!R174 -> 0.405 | I14: =Config!E13 -> 1 | J14: =Config!E13 -> 1 | K14: =Config!N13 -> 0.3 | L14: =Budget!G15 -> 0.4 | M14: =Budget!H15 -> 0.3 | N14: =Budget!J15 -> 0.2 | O14: =Config!O13 -> B3, dry mass = est, thrust iteration for exit velocity | R14: =Config!C13 -> 2026_C_PR_B3_CONFIG10 | V14: =Config!O13 -> B3, dry mass = est, thrust iteration for exit velocity
C15: 2026_C_PR_B3_CONFIG11 | D15: =Budget!F69 -> 5.21037 | E15: =Budget!S122 - Budget!M122 - Budget!N122 - Budget!R122 -> 0.21817645 | F15: =Budget!R122 -> 0.577 | G15: =Budget!S175 -Budget!R175 -> 5.9356949e-05 | H15: =Budget!R175 -> 0.405 | I15: =Config!E14 -> 1 | J15: =Config!E14 -> 1 | K15: =Config!N14 -> 0.3 | L15: =Budget!G16 -> 0.4 | M15: =Budget!H16 -> 0.3 | N15: =Budget!J16 -> 0.2 | O15: =Config!O14 -> B3, dry mass = est, thrust iteration for exit velocity | R15: =Config!C14 -> 2026_C_PR_B3_CONFIG11 | V15: =Config!O14 -> B3, dry mass = est, thrust iteration for exit velocity
C16: 2026_C_PR_B3_CONFIG12 | D16: =Budget!F70 -> 5.21037 | E16: =Budget!S123 - Budget!M123 - Budget!N123 - Budget!R123 -> 0.21817645 | F16: =Budget!R123 -> 0.577 | G16: =Budget!S176 -Budget!R176 -> 5.9356949e-05 | H16: =Budget!R176 -> 0.405 | I16: =Config!E15 -> 1 | J16: =Config!E15 -> 1 | K16: =Config!N15 -> 0.3 | L16: =Budget!G17 -> 0.4 | M16: =Budget!H17 -> 0.3 | N16: =Budget!J17 -> 0.2 | O16: =Config!O15 -> B3, dry mass = est, thrust iteration for exit velocity | R16: =Config!C15 -> 2026_C_PR_B3_CONFIG12 | V16: =Config!O15 -> B3, dry mass = est, thrust iteration for exit velocity
B17: THRUST2 | C17: 2026_C_PR_B3_CONFIG13 | D17: =Budget!F71 -> 5.21037 | E17: =Budget!S124 - Budget!M124 - Budget!N124 - Budget!R124 -> 0.600363 | F17: =Budget!R124 -> 0.577 | G17: =Budget!S177 -Budget!R177 -> 0.29678474 | H17: =Budget!R177 -> 0.405 | I17: =Config!E16 -> 5000 | J17: =Config!E16 -> 5000 | K17: =Config!N16 -> 1500 | L17: =Budget!G18 -> 0.4 | M17: =Budget!H18 -> 0.3 | N17: =Budget!J18 -> 0.2 | O17: =Config!O16 -> B3, dry mass = est + 15%, thrust iteration for exit velocity | Q17: THRUST2 | R17: =Config!C16 -> 2026_C_PR_B3_CONFIG13 | V17: =Config!O16 -> B3, dry mass = est + 15%, thrust iteration for exit velocity
C18: 2026_C_PR_B3_CONFIG14 | D18: =Budget!F72 -> 5.21037 | E18: =Budget!S125 - Budget!M125 - Budget!N125 - Budget!R125 -> 0.6385893 | F18: =Budget!R125 -> 0.577 | G18: =Budget!S178 -Budget!R178 -> 0.32646322 | H18: =Budget!R178 -> 0.405 | I18: =Config!E17 -> 5500 | J18: =Config!E17 -> 5500 | K18: =Config!N17 -> 1650 | L18: =Budget!G19 -> 0.4 | M18: =Budget!H19 -> 0.3 | N18: =Budget!J19 -> 0.2 | O18: =Config!O17 -> B3, dry mass = est + 15%, thrust iteration for exit velocity | R18: =Config!C17 -> 2026_C_PR_B3_CONFIG14 | V18: =Config!O17 -> B3, dry mass = est + 15%, thrust iteration for exit velocity
C19: 2026_C_PR_B3_CONFIG15 | D19: =Budget!F73 -> 5.21037 | E19: =Budget!S126 - Budget!M126 - Budget!N126 - Budget!R126 -> 0.6768156 | F19: =Budget!R126 -> 0.577 | G19: =Budget!S179 -Budget!R179 -> 0.35614169 | H19: =Budget!R179 -> 0.405 | I19: =Config!E18 -> 6000 | J19: =Config!E18 -> 6000 | K19: =Config!N18 -> 1800 | L19: =Budget!G20 -> 0.4 | M19: =Budget!H20 -> 0.3 | N19: =Budget!J20 -> 0.2 | O19: =Config!O18 -> B3, dry mass = est + 15%, thrust iteration for exit velocity | R19: =Config!C18 -> 2026_C_PR_B3_CONFIG15 | V19: =Config!O18 -> B3, dry mass = est + 15%, thrust iteration for exit velocity
C20: 2026_C_PR_B3_CONFIG16 | D20: =Budget!F74 -> 5.21037 | E20: =Budget!S127 - Budget!M127 - Budget!N127 - Budget!R127 -> 0.7150419 | F20: =Budget!R127 -> 0.577 | G20: =Budget!S180 -Budget!R180 -> 0.38582017 | H20: =Budget!R180 -> 0.405 | I20: =Config!E19 -> 6500 | J20: =Config!E19 -> 6500 | K20: =Config!N19 -> 1950 | L20: =Budget!G21 -> 0.4 | M20: =Budget!H21 -> 0.3 | N20: =Budget!J21 -> 0.2 | O20: =Config!O19 -> B3, dry mass = est + 15%, thrust iteration for exit velocity | R20: =Config!C19 -> 2026_C_PR_B3_CONFIG16 | V20: =Config!O19 -> B3, dry mass = est + 15%, thrust iteration for exit velocity
C21: 2026_C_PR_B3_CONFIG17 | D21: =Budget!F75 -> 5.21037 | E21: =Budget!S128 - Budget!M128 - Budget!N128 - Budget!R128 -> 0.7532682 | F21: =Budget!R128 -> 0.577 | G21: =Budget!S181 -Budget!R181 -> 0.41549864 | H21: =Budget!R181 -> 0.405 | I21: =Config!E20 -> 7000 | J21: =Config!E20 -> 7000 | K21: =Config!N20 -> 2100 | L21: =Budget!G22 -> 0.4 | M21: =Budget!H22 -> 0.3 | N21: =Budget!J22 -> 0.2 | O21: =Config!O20 -> B3, dry mass = est + 15%, thrust iteration for exit velocity | R21: =Config!C20 -> 2026_C_PR_B3_CONFIG17 | V21: =Config!O20 -> B3, dry mass = est + 15%, thrust iteration for exit velocity
C22: 2026_C_PR_B3_CONFIG18 | D22: =Budget!F76 -> 5.21037 | E22: =Budget!S129 - Budget!M129 - Budget!N129 - Budget!R129 -> 9.9658064 | F22: =Budget!R129 -> 0.577 | G22: =Budget!S182 -Budget!R182 -> 7.0201007 | H22: =Budget!R182 -> 0.405 | I22: =Config!E21 -> 7500 | J22: =Config!E21 -> 7500 | K22: =Config!N21 -> 38250 | L22: =Budget!G23 -> 0.4 | M22: =Budget!H23 -> 5.1 | N22: =Budget!J23 -> 0.2 | O22: =Config!O21 -> B3, dry mass = est + 15%, thrust iteration for exit velocity | R22: =Config!C21 -> 2026_C_PR_B3_CONFIG18 | S22: 2740 | T22: 3.688 | U22: 31.696 | V22: =Config!O21 -> B3, dry mass = est + 15%, thrust iteration for exit velocity
C23: 2026_C_PR_B3_CONFIG19 | D23: =Budget!F77 -> 5.21037 | E23: =Budget!S130 - Budget!M130 - Budget!N130 - Budget!R130 -> 10.004033 | F23: =Budget!R130 -> 0.577 | G23: =Budget!S183 -Budget!R183 -> 7.0497791 | H23: =Budget!R183 -> 0.405 | I23: =Config!E22 -> 8000 | J23: =Config!E22 -> 8000 | K23: =Config!N22 -> 38400 | L23: =Budget!G24 -> 0.4 | M23: =Budget!H24 -> 4.8 | N23: =Budget!J24 -> 0.2 | O23: =Config!O22 -> B3, dry mass = est + 15%, thrust iteration for exit velocity | R23: =Config!C22 -> 2026_C_PR_B3_CONFIG19 | S23: 2777 | T23: 3.666 | U23: 32.817 | V23: =Config!O22 -> B3, dry mass = est + 15%, thrust iteration for exit velocity
C24: 2026_C_PR_B3_CONFIG20 | D24: =Budget!F78 -> 5.21037 | E24: =Budget!S131 - Budget!M131 - Budget!N131 - Budget!R131 -> 0.21817645 | F24: =Budget!R131 -> 0.577 | G24: =Budget!S184 -Budget!R184 -> 5.9356949e-05 | H24: =Budget!R184 -> 0.405 | I24: =Config!E23 -> 1 | J24: =Config!E23 -> 1 | K24: =Config!N23 -> 0.3 | L24: =Budget!G25 -> 0.4 | M24: =Budget!H25 -> 0.3 | N24: =Budget!J25 -> 0.2 | O24: =Config!O23 -> B3, dry mass = est + 15%, thrust iteration for exit velocity | R24: =Config!C23 -> 2026_C_PR_B3_CONFIG20 | V24: =Config!O23 -> B3, dry mass = est + 15%, thrust iteration for exit velocity
C25: 2026_C_PR_B3_CONFIG21 | D25: =Budget!F79 -> 5.21037 | E25: =Budget!S132 - Budget!M132 - Budget!N132 - Budget!R132 -> 0.21817645 | F25: =Budget!R132 -> 0.577 | G25: =Budget!S185 -Budget!R185 -> 5.9356949e-05 | H25: =Budget!R185 -> 0.405 | I25: =Config!E24 -> 1 | J25: =Config!E24 -> 1 | K25: =Config!N24 -> 0.3 | L25: =Budget!G26 -> 0.4 | M25: =Budget!H26 -> 0.3 | N25: =Budget!J26 -> 0.2 | O25: =Config!O24 -> B3, dry mass = est + 15%, thrust iteration for exit velocity | R25: =Config!C24 -> 2026_C_PR_B3_CONFIG21 | V25: =Config!O24 -> B3, dry mass = est + 15%, thrust iteration for exit velocity
C26: 2026_C_PR_B3_CONFIG22 | D26: =Budget!F80 -> 5.21037 | E26: =Budget!S133 - Budget!M133 - Budget!N133 - Budget!R133 -> 0.21817645 | F26: =Budget!R133 -> 0.577 | G26: =Budget!S186 -Budget!R186 -> 5.9356949e-05 | H26: =Budget!R186 -> 0.405 | I26: =Config!E25 -> 1 | J26: =Config!E25 -> 1 | K26: =Config!N25 -> 0.3 | L26: =Budget!G27 -> 0.4 | M26: =Budget!H27 -> 0.3 | N26: =Budget!J27 -> 0.2 | O26: =Config!O25 -> B3, dry mass = est + 15%, thrust iteration for exit velocity | R26: =Config!C25 -> 2026_C_PR_B3_CONFIG22 | V26: =Config!O25 -> B3, dry mass = est + 15%, thrust iteration for exit velocity
C27: 2026_C_PR_B3_CONFIG23 | D27: =Budget!F81 -> 5.21037 | E27: =Budget!S134 - Budget!M134 - Budget!N134 - Budget!R134 -> 0.21817645 | F27: =Budget!R134 -> 0.577 | G27: =Budget!S187 -Budget!R187 -> 5.9356949e-05 | H27: =Budget!R187 -> 0.405 | I27: =Config!E26 -> 1 | J27: =Config!E26 -> 1 | K27: =Config!N26 -> 0.3 | L27: =Budget!G28 -> 0.4 | M27: =Budget!H28 -> 0.3 | N27: =Budget!J28 -> 0.2 | O27: =Config!O26 -> B3, dry mass = est + 15%, thrust iteration for exit velocity | R27: =Config!C26 -> 2026_C_PR_B3_CONFIG23 | V27: =Config!O26 -> B3, dry mass = est + 15%, thrust iteration for exit velocity
C28: 2026_C_PR_B3_CONFIG24 | D28: =Budget!F82 -> 5.21037 | E28: =Budget!S135 - Budget!M135 - Budget!N135 - Budget!R135 -> 0.21817645 | F28: =Budget!R135 -> 0.577 | G28: =Budget!S188 -Budget!R188 -> 5.9356949e-05 | H28: =Budget!R188 -> 0.405 | I28: =Config!E27 -> 1 | J28: =Config!E27 -> 1 | K28: =Config!N27 -> 0.3 | L28: =Budget!G29 -> 0.4 | M28: =Budget!H29 -> 0.3 | N28: =Budget!J29 -> 0.2 | O28: =Config!O27 -> B3, dry mass = est + 15%, thrust iteration for exit velocity | R28: =Config!C27 -> 2026_C_PR_B3_CONFIG24 | V28: =Config!O27 -> B3, dry mass = est + 15%, thrust iteration for exit velocity
B29: IMPULSE1 | C29: 2026_C_PR_B3_CONFIG25 | D29: =Budget!F83 -> 5.21037 | E29: =Budget!S136 - Budget!M136 - Budget!N136 - Budget!R136 -> 9.6727381 | F29: =Budget!R136 -> 0.577 | G29: =Budget!S189 -Budget!R189 -> 6.8077854 | H29: =Budget!R189 -> 0.405 | I29: =Config!E28 -> 7000 | J29: =Config!E28 -> 7000 | K29: =Config!N28 -> 37100 | L29: =Budget!G30 -> 0.4 | M29: =Budget!H30 -> 5.3 | N29: =Budget!J30 -> 0.2 | O29: =Config!O28 -> B3, dry mass = est, impulse iteration for apogee | Q29: IMPULSE1 | R29: =Config!C28 -> 2026_C_PR_B3_CONFIG25 | S29: 3008 | T29: 3.622 | U29: 32.087 | V29: =Config!O28 -> B3, dry mass = est, impulse iteration for apogee
C30: 2026_C_PR_B3_CONFIG26 | D30: =Budget!F84 -> 5.21037 | E30: =Budget!S137 - Budget!M137 - Budget!N137 - Budget!R137 -> 10.309843 | F30: =Budget!R137 -> 0.577 | G30: =Budget!S190 -Budget!R190 -> 7.2643773 | H30: =Budget!R190 -> 0.405 | I30: =Config!E29 -> 7000 | J30: =Config!E29 -> 7000 | K30: =Config!N29 -> 39600 | L30: =Budget!G31 -> 0.4 | M30: =Budget!H31 -> 5.6571429 | N30: =Budget!J31 -> 0.2 | O30: =Config!O29 -> B3, dry mass = est, impulse iteration for apogee | R30: =Config!C29 -> 2026_C_PR_B3_CONFIG26 | S30: 3315 | T30: 3.596 | U30: 31.929 | V30: =Config!O29 -> B3, dry mass = est, impulse iteration for apogee
C31: 2026_C_PR_B3_CONFIG27 | D31: =Budget!F85 -> 5.21037 | E31: =Budget!S138 - Budget!M138 - Budget!N138 - Budget!R138 -> 9.9275801 | F31: =Budget!R138 -> 0.577 | G31: =Budget!S191 -Budget!R191 -> 6.9904222 | H31: =Budget!R191 -> 0.405 | I31: =Config!E30 -> 7000 | J31: =Config!E30 -> 7000 | K31: =Config!N30 -> 38100 | L31: =Budget!G32 -> 0.4 | M31: =Budget!H32 -> 5.4428571 | N31: =Budget!J32 -> 0.2 | O31: =Config!O30 -> B3, dry mass = est, impulse iteration for apogee | R31: =Config!C30 -> 2026_C_PR_B3_CONFIG27 | S31: 3129 | T31: 3.612 | U31: 32.016 | V31: =Config!O30 -> B3, dry mass = est, impulse iteration for apogee
C32: 2026_C_PR_B3_CONFIG28 | D32: =Budget!F86 -> 5.21037 | E32: =Budget!S139 - Budget!M139 - Budget!N139 - Budget!R139 -> 10.055001 | F32: =Budget!R139 -> 0.577 | G32: =Budget!S192 -Budget!R192 -> 7.0817406 | H32: =Budget!R192 -> 0.405 | I32: =Config!E31 -> 7000 | J32: =Config!E31 -> 7000 | K32: =Config!N31 -> 38600 | L32: =Budget!G33 -> 0.4 | M32: =Budget!H33 -> 5.5142857 | N32: =Budget!J33 -> 0.2 | O32: =Config!O31 -> B3, dry mass = est, impulse iteration for apogee | R32: =Config!C31 -> 2026_C_PR_B3_CONFIG28 | S32: 3190 | T32: 3.606 | U32: 31.991 | V32: =Config!O31 -> B3, dry mass = est, impulse iteration for apogee
C33: 2026_C_PR_B3_CONFIG29 | D33: =Budget!F87 -> 5.21037 | E33: =Budget!S140 - Budget!M140 - Budget!N140 - Budget!R140 -> 10.118712 | F33: =Budget!R140 -> 0.577 | G33: =Budget!S193 -Budget!R193 -> 7.1273998 | H33: =Budget!R193 -> 0.405 | I33: =Config!E32 -> 7000 | J33: =Config!E32 -> 7000 | K33: =Config!N32 -> 38850 | L33: =Budget!G34 -> 0.4 | M33: =Budget!H34 -> 5.55 | N33: =Budget!J34 -> 0.2 | O33: =Config!O32 -> B3, dry mass = est, impulse iteration for apogee | R33: =Config!C32 -> 2026_C_PR_B3_CONFIG29 | S33: 3220 | T33: 3.604 | U33: 31.975 | V33: =Config!O32 -> B3, dry mass = est, impulse iteration for apogee
C34: 2026_C_PR_B3_CONFIG30 | D34: =Budget!F88 -> 5.21037 | E34: =Budget!S141 - Budget!M141 - Budget!N141 - Budget!R141 -> 0.21843129 | F34: =Budget!R141 -> 0.577 | G34: =Budget!S194 -Budget!R194 -> 0.00024199371 | H34: =Budget!R194 -> 0.405 | I34: =Config!E33 -> 1 | J34: =Config!E33 -> 1 | K34: =Config!N33 -> 1.3 | L34: =Budget!G35 -> 0.4 | M34: =Budget!H35 -> 1.3 | N34: =Budget!J35 -> 0.2 | O34: =Config!O33 -> B3, dry mass = est, impulse iteration for apogee | R34: =Config!C33 -> 2026_C_PR_B3_CONFIG30 | V34: =Config!O33 -> B3, dry mass = est, impulse iteration for apogee
B35: IMPULSE2 | C35: 2026_C_PR_B3_CONFIG31 | D35: =Budget!F89 -> 5.21037 | E35: =Budget!S142 - Budget!M142 - Budget!N142 - Budget!R142 -> 10.258875 | F35: =Budget!R142 -> 0.577 | G35: =Budget!S195 -Budget!R195 -> 7.2324159 | H35: =Budget!R195 -> 0.405 | I35: =Config!E34 -> 8000 | J35: =Config!E34 -> 8000 | K35: =Config!N34 -> 39400 | L35: =Budget!G36 -> 0.4 | M35: =Budget!H36 -> 4.925 | N35: =Budget!J36 -> 0.2 | O35: =Config!O34 -> B3, dry mass = est + 15%, impulse iteration for apogee | Q35: IMPULSE2 | R35: =Config!C34 -> 2026_C_PR_B3_CONFIG31 | S35: 3192 | T35: 3.655 | U35: 32.743 | V35: =Config!O34 -> B3, dry mass = est + 15%, impulse iteration for apogee
C36: 2026_C_PR_B3_CONFIG32 | D36: =Budget!F90 -> 5.21037 | E36: =Budget!S143 - Budget!M143 - Budget!N143 - Budget!R143 -> 10.386296 | F36: =Budget!R143 -> 0.577 | G36: =Budget!S196 -Budget!R196 -> 7.3237343 | H36: =Budget!R196 -> 0.405 | I36: =Config!E35 -> 8000 | J36: =Config!E35 -> 8000 | K36: =Config!N35 -> 39900 | L36: =Budget!G37 -> 0.4 | M36: =Budget!H37 -> 4.9875 | N36: =Budget!J37 -> 0.2 | O36: =Config!O35 -> B3, dry mass = est + 15%, impulse iteration for apogee | R36: =Config!C35 -> 2026_C_PR_B3_CONFIG32 | S36: 3253 | T36: 3.651 | U36: 32.713 | V36: =Config!O35 -> B3, dry mass = est + 15%, impulse iteration for apogee
C37: 2026_C_PR_B3_CONFIG33 | D37: =Budget!F91 -> 5.21037 | E37: =Budget!S144 - Budget!M144 - Budget!N144 - Budget!R144 -> 0.82997564 | F37: =Budget!R144 -> 0.577 | G37: =Budget!S197 -Budget!R197 -> 0.47503823 | H37: =Budget!R197 -> 0.405 | I37: =Config!E36 -> 8000 | J37: =Config!E36 -> 8000 | K37: =Config!N36 -> 2401 | L37: =Budget!G38 -> 0.4 | M37: =Budget!H38 -> 0.300125 | N37: =Budget!J38 -> 0.2 | O37: =Config!O36 -> B3, dry mass = est + 15%, impulse iteration for apogee | R37: =Config!C36 -> 2026_C_PR_B3_CONFIG33 | V37: =Config!O36 -> B3, dry mass = est + 15%, impulse iteration for apogee
C38: 2026_C_PR_B3_CONFIG34 | D38: =Budget!F92 -> 5.21037 | E38: =Budget!S145 - Budget!M145 - Budget!N145 - Budget!R145 -> 0.82997564 | F38: =Budget!R145 -> 0.577 | G38: =Budget!S198 -Budget!R198 -> 0.47503823 | H38: =Budget!R198 -> 0.405 | I38: =Config!E37 -> 8000 | J38: =Config!E37 -> 8000 | K38: =Config!N37 -> 2401 | L38: =Budget!G39 -> 0.4 | M38: =Budget!H39 -> 0.300125 | N38: =Budget!J39 -> 0.2 | O38: =Config!O37 -> B3, dry mass = est + 15%, impulse iteration for apogee | R38: =Config!C37 -> 2026_C_PR_B3_CONFIG34 | V38: =Config!O37 -> B3, dry mass = est + 15%, impulse iteration for apogee
C39: 2026_C_PR_B1_CONFIG35 | D39: =Budget!F93 -> 5.21037 | E39: =Budget!S146 - Budget!M146 - Budget!N146 - Budget!R146 -> 0.21843129 | F39: =Budget!R146 -> 2.67 | G39: =Budget!S199 -Budget!R199 -> 0.16585011 | H39: =Budget!R199 -> 0.527 | I39: =Config!E38 -> 1 | J39: =Config!E38 -> 1 | K39: =Config!N38 -> 1.3 | L39: =Budget!G40 -> 0.4 | M39: =Budget!H40 -> 1.3 | N39: =Budget!J40 -> 0.2 | O39: =Config!O38 -> B3, dry mass = est + 15%, impulse iteration for apogee | R39: =Config!C38 -> 2026_C_PR_B1_CONFIG35 | V39: =Config!O38 -> B3, dry mass = est + 15%, impulse iteration for apogee
C40: 2026_C_PR_B1_CONFIG36 | D40: =Budget!F94 -> 5.21037 | E40: =Budget!S147 - Budget!M147 - Budget!N147 - Budget!R147 -> 0.21843129 | F40: =Budget!R147 -> 2.67 | G40: =Budget!S200 -Budget!R200 -> 0.16585011 | H40: =Budget!R200 -> 0.527 | I40: =Config!E39 -> 1 | J40: =Config!E39 -> 1 | K40: =Config!N39 -> 1.3 | L40: =Budget!G41 -> 0.4 | M40: =Budget!H41 -> 1.3 | N40: =Budget!J41 -> 0.2 | O40: =Config!O39 -> B3, dry mass = est + 15%, impulse iteration for apogee | R40: =Config!C39 -> 2026_C_PR_B1_CONFIG36 | V40: =Config!O39 -> B3, dry mass = est + 15%, impulse iteration for apogee
B41: ISP | C41: 2026_C_PR_B1_CONFIG37 | D41: =Budget!F95 -> 5.21037 | E41: =Budget!S148 - Budget!M148 - Budget!N148 - Budget!R148 -> 12.098834 | F41: =Budget!R148 -> 2.67 | G41: =Budget!S201 -Budget!R201 -> 8.6530422 | H41: =Budget!R201 -> 0.527 | I41: =Config!E40 -> 7000 | J41: =Config!E40 -> 7000 | K41: =Config!N40 -> 38850 | L41: =Budget!G42 -> 0.4 | M41: =Budget!H42 -> 5.55 | N41: =Budget!J42 -> 0.2 | O41: =Config!O40 -> B3, dry mass = est, ISP iteration | Q41: ISP | R41: =Config!C40 -> 2026_C_PR_B1_CONFIG37 | S41: 3146 | T41: 3.532 | U41: 31.561 | V41: =Config!O40 -> B3, dry mass = est, ISP iteration
...

Sheet ISP
B2: Nominal Thurst [N] | C2: ISP [s] | D2: core O/F [-] | E2: Mass flow tot core [kg/s] | F2: Mass flow ox [kg/s] | G2: Mass flow fuel core [kg/s] | H2: Mass flow fuel [kg/s] | I2: Total impulse [Ns]
B3: 6500 | C3: 200 | D3: 1.5 | E3: =B3/(C3*9.81) -> 3.312946 | F3: =E3/(1+1/D3) -> 1.9877676 | G3: =E3 / (1 +D3 ) -> 1.3251784 | H3: =1.075*G3 -> 1.4245668
B4: 6500 | C4: 201 | D4: 1.5 | E4: =B4/(C4*9.81) -> 3.2964637 | F4: =E4/(1+1/D4) -> 1.9778782 | G4: =E4 / (1 +D4 ) -> 1.3185855 | H4: =1.075*G4 -> 1.4174794
B5: 6500 | C5: 202 | D5: 1.5 | E5: =B5/(C5*9.81) -> 3.2801445 | F5: =E5/(1+1/D5) -> 1.9680867 | G5: =E5 / (1 +D5 ) -> 1.3120578 | H5: =1.075*G5 -> 1.4104621
B6: 6500 | C6: 203 | D6: 1.5 | E6: =B6/(C6*9.81) -> 3.2639862 | F6: =E6/(1+1/D6) -> 1.9583917 | G6: =E6 / (1 +D6 ) -> 1.3055945 | H6: =1.075*G6 -> 1.4035141
B7: 6500 | C7: 204 | D7: 1.5 | E7: =B7/(C7*9.81) -> 3.2479862 | F7: =E7/(1+1/D7) -> 1.9487917 | G7: =E7 / (1 +D7 ) -> 1.2991945 | H7: =1.075*G7 -> 1.3966341
B8: 6500 | C8: 205 | D8: 1.5 | E8: =B8/(C8*9.81) -> 3.2321424 | F8: =E8/(1+1/D8) -> 1.9392854 | G8: =E8 / (1 +D8 ) -> 1.292857 | H8: =1.075*G8 -> 1.3898212
B9: 6500 | C9: 206 | D9: 1.5 | E9: =B9/(C9*9.81) -> 3.2164524 | F9: =E9/(1+1/D9) -> 1.9298714 | G9: =E9 / (1 +D9 ) -> 1.286581 | H9: =1.075*G9 -> 1.3830745
B10: 6500 | C10: 207 | D10: 1.5 | E10: =B10/(C10*9.81) -> 3.200914 | F10: =E10/(1+1/D10) -> 1.9205484 | G10: =E10 / (1 +D10 ) -> 1.2803656 | H10: =1.075*G10 -> 1.376393
B11: 6500 | C11: 208 | D11: 1.5 | E11: =B11/(C11*9.81) -> 3.185525 | F11: =E11/(1+1/D11) -> 1.911315 | G11: =E11 / (1 +D11 ) -> 1.27421 | H11: =1.075*G11 -> 1.3697757
B12: 6500 | C12: 209 | D12: 1.5 | E12: =B12/(C12*9.81) -> 3.1702832 | F12: =E12/(1+1/D12) -> 1.9021699 | G12: =E12 / (1 +D12 ) -> 1.2681133 | H12: =1.075*G12 -> 1.3632218
B13: 6500 | C13: 210 | D13: 1.5 | E13: =B13/(C13*9.81) -> 3.1551866 | F13: =E13/(1+1/D13) -> 1.893112 | G13: =E13 / (1 +D13 ) -> 1.2620747 | H13: =1.075*G13 -> 1.3567303
B14: 6500 | C14: 211 | D14: 1.5 | E14: =B14/(C14*9.81) -> 3.1402331 | F14: =E14/(1+1/D14) -> 1.8841399 | G14: =E14 / (1 +D14 ) -> 1.2560933 | H14: =1.075*G14 -> 1.3503003
... B63: 6500 | C63: 260 | D63: 1.5 | E63: =B63/(C63*9.81) -> 2.54842 | F63: =E63/(1+1/D63) -> 1.529052 | G63: =E63 / (1 +D63 ) -> 1.019368 | H63: =1.075*G63 -> 1.0958206
